Workbook

Sheet MODELO EQUÍL. E CARGA
B2: ETA BRASÍLIA
B3: ESTUDO DE OTIMIZAÇÃO DA COAGULAÇÃO COM UTILIZAÇÃO DA ANÁLISADOR DE CARGA SCV "EM LINHA" E EQUILÍBRIO QUÍMICO H20 COAGULADA/ PRÉ-TRATAMENTO
B4: LADOS PAR E ÍMPAR
B5: DATA: | E5: TURNO I:
E6: TURNO II:
B8: HORA | C8: Vazões H20 | G8: DOSAGENS | J8: FLOC. GRADIENTES (s-1) | M8: LABORATÓRIO ETA-BRUTA COMPOSTA/ FILTRADA | S8: FLOCULADOR / FLOTADOR PAR | AA8: FLOCULADOR / FLOTADOR ÍMPAR
B9: (hh:mm) | C9: TOR (L/s) | D9: SM (L/s) | E9: BNN (L/s) | F9: TOTAL (L/s) | G9: CAL PRÉ (S/N) | H9: PAC (mg/L) | I9: CARGA (CSV) | J9: 1ª Camara | K9: 2ª Camara | L9: 3ª Camara | M9: TEMP (°C) | N9: pH | O9: TURB (uT) | P9: COR (uC) | Q9: ALC. (mg/L) | R9: TURB. FILT. (uT) | S9: Nº FLOC. | T9: Nº FLOT. | U9: Pressão Sat. Média (bar) | V9: Vazão Rec. Média (L/s) | W9: pH | X9: ALC. (mg/L) | Y9: TURB PAPEL FILTRO | Z9: TURB. FLOT. CLP | AA9: Nº FLOC. | AB9: Nº FLOT. | AC9: Pressão Sat. Média (bar) | AD9: Vazão Rec. (L/s) | AE9: pH | AF9: ALC. (mg/L) | AG9: TURB PAPEL FILTRO | AH9: TURB. FLOT. CLP
B10: 0.3125
B11: 0.39583333
B12: 0.47916667
B13: 0.5625
B14: 0.64583333
B15: 0.72916667
B16: 0.8125
B17: 0.89583333
B18: 0.97916667
B19: 0.0625
B20: 0.14583333
B21: 0.22916667
B23: OBSERVAÇÕES:

Sheet MODELO EQUÍLIBRIO QUÍMICO
B2: ETA BRASÍLIA
B3: ESTUDO EQUILÍBRIO QUÍMICO H20 COAGULADA/ PRÉ-TRATAMENTO
B4: LADOS PAR E ÍMPAR
B5: DATA: | E5: TURNO I:
E6: TURNO II:
B8: HORA | C8: Vazões H20 | G8: DOSAGENS | I8: FLOC. GRADIENTES (s-1) | L8: LABORATÓRIO ETA-BRUTA COMPOSTA/ FILTRADA | R8: FLOCULADOR / FLOTADOR PAR - N° 6 | Z8: FLOCULADOR / FLOTADOR ÍMPAR - N° 5
C9: TOR (L/s) | D9: SM (L/s) | E9: BNN (L/s) | F9: TOTAL (L/s) | G9: CAL PRÉ (S/N) | H9: PAC (mg/L) | I9: 1ª Camara | J9: 2ª Camara | K9: 3ª Camara | L9: TEMP (°C) | M9: pH | N9: TURB (uT) | O9: COR (uC) | P9: ALC. (mg/L) | Q9: TURB. FILT. (uT) | R9: Nº FLOC. | S9: Nº FLOT. | T9: Pressão Sat. (bar) | U9: Vazão Rec. (L/s) | V9: pH | W9: ALC. (mg/L) | X9: TURB PAPEL FILTRO | Y9: TURB. FLOT. CLP | Z9: Nº FLOC. | AA9: Nº FLOT. | AB9: Pressão Sat. (bar) | AC9: Vazão Rec. (L/s) | AD9: pH | AE9: ALC. (mg/L) | AF9: TURB PAPEL FILTRO | AG9: TURB. FLOT. CLP
B10: 0.3125
B11: 0.39583333
B12: 0.47916667
B13: 0.5625
B14: 0.64583333
B15: 0.72916667
B16: 0.8125
B17: 0.89583333
B18: 0.97916667
B19: 0.0625
B20: 0.14583333
B21: 0.22916667
B23: OBSERVAÇÕES:

Sheet 21.04
B2: ETA BRASÍLIA | C2: VA
B3: ESTUDO EQUILÍBRIO QUÍMICO H20 COAGULADA
B4: LADOS PAR E ÍMAR
B5: DATA: | C5: 46136 | E5: TURNO I | F5: Andréa / Jamir
E6: TURNO II | F6: Maciel / Mathias
B8: HORA | C8: Vazões H20 | G8: DOSAGENS | I8: FLOCULAÇÃO GRADIENTES | L8: LABORATÓRIO ETA-BRUTA COMPOSTA | Q8: FLOCULADOR / FLOTADOR PAR - N° 6 | U8: FLOCULADOR / FLOTADOR ÍMPAR - N° 5
C9: TOR (l/s) | D9: SM (l/s) | E9: BNN (l/s) | F9: TOTAL (l/s) | G9: CAL (s/n) | H9: PAC (mg/l) | I9: 1ª Camara | J9: 2ª Camara | K9: 3ª Camara | L9: TEMP (°c) | M9: PH | N9: TURB | O9: COR | P9: ALC. (mg/l) | Q9: PH | R9: ALC. (mg/l) | S9: TURB PAPEL FILTRO | T9: TURB. FLOT. CLP | U9: PH | V9: ALC. (mg/l) | W9: TURB PAPEL FILTRO | X9: TURB. FLOT. CLP
B10: 0.3125 | C10: 1918 | D10: - | E10: 500 | F10: 1996 | G10: S | H10: 3.4 | I10: 90 | J10: 90 | K10: 90 | L10: 23.3 | M10: 6.8 | N10: 3.84 | O10: 16 | P10: 7.1 | Q10: 6.8 | R10: 8.1 | S10: 0.14 | T10: 0.86 | U10: 6.9 | V10: 7.4 | W10: 0.14 | X10: 0.87
B11: 0.39583333 | C11: 590 | D11: - | E11: 525 | F11: 1300 | G11: S | H11: 3.4 | I11: 90 | J11: 90 | K11: 90 | L11: 23.6 | M11: 6.8 | N11: 3.59 | O11: 14 | P11: 7.2 | Q11: 6.9 | R11: 8 | S11: 0.19 | T11: 1.23 | U11: 6.9 | V11: 6.8 | W11: 0.2 | X11: 1.62
B12: 0.47916667 | C12: 590 | D12: - | E12: 525 | F12: 1291 | G12: S | H12: 3.4 | I12: 90 | J12: 90 | K12: 90 | L12: 24.3 | M12: 6.7 | N12: 4.15 | O12: 17 | P12: 7.4 | Q12: 6.9 | R12: 8.2 | S12: 0.16 | T12: 1.52 | U12: 6.8 | V12: 7.4 | W12: 0.18 | X12: 2.2
B13: 0.5625 | C13: 590 | D13: - | E13: 525 | F13: 12190 | G13: S | H13: 3.4 | I13: 90 | J13: 90 | K13: 90 | L13: 24.8 | M13: 6.8 | N13: 4.68 | O13: 19 | P13: 7.9 | Q13: 6.9 | R13: 9.4 | S13: 0.14 | T13: 1.64 | U13: 6.9 | V13: 8.1 | W13: 0.18 | X13: 1.51
B14: 0.64583333 | C14: 1240 | D14: - | E14: 500 | F14: 1980 | G14: S | H14: 3.4 | I14: 90 | J14: 90 | K14: 90 | L14: 25.4 | M14: 6.8 | N14: 4.08 | O14: 14 | P14: 6.9 | Q14: 6.8 | R14: 6.7 | S14: 0.23 | T14: 1.33 | U14: 6.7 | V14: 7.3 | W14: 0.25 | X14: 1.56
B15: 0.72916667 | C15: 1201 | D15: - | E15: 499.2 | F15: 1906 | G15: S | H15: 3.4 | I15: 90 | J15: 90 | K15: 90 | L15: 25 | M15: 6.7 | N15: 4.4 | O15: 16 | P15: 5.7 | Q15: 6.7 | R15: 6 | S15: 0.16 | T15: 1.23 | U15: 6.7 | V15: 5.5 | W15: 0.21 | X15: 1.68
B16: 0.8125 | C16: 1112 | D16: 86 | E16: 500 | F16: 1828 | G16: S | H16: 3.4 | I16: 90 | J16: 90 | K16: 90 | L16: 24.7 | M16: 6.8 | N16: 4.38 | O16: 15 | P16: 9.3 | Q16: 6.8 | R16: 8.1 | S16: 0.24 | T16: 1.11 | U16: 6.8 | V16: 9.8 | W16: 0.29 | X16: 1.91
B17: 0.89583333 | C17: 1232 | D17: 87 | E17: 500 | F17: 1845 | G17: S | H17: 3.4 | I17: 90 | J17: 90 | K17: 90 | L17: 24.5 | M17: 6.8 | N17: 4.21 | O17: 13 | P17: 8.6 | Q17: 6.8 | R17: 8.5 | S17: 0.2 | T17: 0.88 | U17: 6.8 | V17: 8.7 | W17: 0.25 | X17: 1.09
B18: 0.97916667 | C18: 1208 | D18: 85 | E18: 500 | F18: 1834 | G18: S | H18: 3.4 | I18: 90 | J18: 90 | K18: 90 | L18: 24.2 | M18: 6.7 | N18: 3.84 | O18: 15 | P18: 8.8 | Q18: 6.8 | R18: 7.3 | S18: 0.21 | T18: 0.85 | U18: 6.8 | V18: 6.9 | W18: 0.17 | X18: 0.78
B19: 0.0625 | C19: 1207 | D19: 88 | E19: 500 | F19: 1915 | G19: S | H19: 3.4 | I19: 90 | J19: 90 | K19: 90 | L19: 24.1 | M19: 6.8 | N19: 4.02 | O19: 17 | P19: 9.4 | Q19: 6.8 | R19: 9.1 | S19: 0.16 | T19: 1.14 | U19: 6.7 | V19: 7.1 | W19: 0.17 | X19: 1.2
B20: 0.14583333 | C20: 1229 | D20: 88 | E20: 500 | F20: 1824 | G20: S | H20: 3.4 | I20: 90 | J20: 90 | K20: 90 | L20: 23.9 | M20: 6.8 | N20: 3.98 | O20: 18 | P20: 9 | Q20: 6.8 | R20: 9.2 | S20: 0.18 | T20: 0.97 | U20: 6.7 | V20: 8.7 | W20: 0.21 | X20: 1.14
B21: 0.22916667 | C21: 1104 | D21: 81 | E21: 499 | F21: 1919 | G21: S | H21: 3.4 | I21: 90 | J21: 90 | K21: 90 | L21: 23.4 | M21: 6.8 | N21: 4.88 | O21: 18 | P21: 8.9 | Q21: 6.8 | R21: 9.4 | S21: 0.15 | T21: 0.86 | U21: 6.8 | V21: 7.8 | W21: 0.21 | X21: 1.01
B23: OBSERVAÇÕES:

Sheet 20.04
B2: ETA BRASÍLIA | C2: VA
B3: ESTUDO EQUILÍBRIO QUÍMICO H20 COAGULADA
B4: LADOS PAR E ÍMAR
B5: DATA: | C5: 46132 | E5: TURNO I | F5: Andréa / Pierry
E6: TURNO II | F6: Leandro / Cláudio
B8: HORA | C8: Vazões H20 | G8: DOSAGENS | I8: FLOCULAÇÃO GRADIENTES | L8: LABORATÓRIO ETA-BRUTA COMPOSTA | Q8: FLOCULADOR / FLOTADOR PAR - N° 6 | U8: FLOCULADOR / FLOTADOR ÍMPAR - N° 5
C9: TOR (l/s) | D9: SM (l/s) | E9: BNN (l/s) | F9: TOTAL (l/s) | G9: CAL (s/n) | H9: PAC (mg/l) | I9: 1ª Camara | J9: 2ª Camara | K9: 3ª Camara | L9: TEMP (°c) | M9: PH | N9: TURB | O9: COR | P9: ALC. (mg/l) | Q9: PH | R9: ALC. (mg/l) | S9: TURB PAPEL FILTRO | T9: TURB. FLOT. CLP | U9: PH | V9: ALC. (mg/l) | W9: TURB PAPEL FILTRO | X9: TURB. FLOT. CLP
B10: 0.3125 | C10: 1080 | D10: - | E10: 500.2 | F10: 1877 | G10: S | H10: 3.6 | I10: 90 | J10: 90 | K10: 90 | L10: 23.3 | M10: 6.8 | N10: 3.71 | O10: 15 | P10: 6.5 | Q10: 6.8 | R10: 6.5 | S10: 0.12 | T10: 0.76 | U10: 6.6 | V10: 6.8 | W10: 0.14 | X10: 1.05
B11: 0.39583333 | C11: 1191.3 | D11: - | E11: 500.7 | F11: 1878 | G11: S | H11: 3.2 | I11: 90 | J11: 90 | K11: 90 | L11: 23.6 | M11: 6.8 | N11: 4.58 | O11: 21 | P11: 6.2 | Q11: 6.7 | R11: 8.1 | S11: 0.17 | T11: 0.86 | U11: 6.7 | V11: 7.3 | W11: 0.25 | X11: 1.21
B12: 0.47916667 | C12: 1191 | D12: - | E12: 500 | F12: 1889 | H12: 3.2 | I12: 90 | J12: 90 | K12: 90 | L12: 24.2 | M12: 6.7 | N12: 4.37 | O12: 16 | P12: 6.2 | Q12: 6.7 | R12: 5.4 | S12: 0.15 | T12: 1.1 | U12: 6.7 | V12: 6.1 | W12: 0.19 | X12: 1.18
B13: 0.5625 | C13: 1236.4 | D13: - | E13: 499.4 | F13: 1881 | G13: S | H13: 3.4 | I13: 90 | J13: 90 | K13: 90 | L13: 24.7 | M13: 6.8 | N13: 4.61 | O13: 16 | P13: 6.4 | Q13: 6.8 | R13: 7.3 | S13: 0.32 | T13: 1.38 | U13: 6.7 | V13: 6.8 | W13: 0.23 | X13: 2.48
B14: 0.64583333 | C14: 1768 | D14: - | E14: 499.9 | F14: 2364 | G14: S | H14: 3.4 | I14: 90 | J14: 90 | K14: 90 | L14: 25.2 | M14: 6.7 | N14: 3.95 | O14: 19 | P14: 6.6 | Q14: 6.7 | R14: 6.5 | S14: 0.25 | T14: 0.97 | U14: 6.7 | V14: 7.3 | W14: 0.34 | X14: 1.39
B15: 0.72916667 | C15: 1602 | D15: - | E15: 500 | F15: 2370 | G15: S | H15: 3.4 | I15: 90 | J15: 90 | K15: 90 | L15: 25.1 | M15: 6.7 | N15: 3.54 | O15: 18 | P15: 6.2 | Q15: 6.8 | R15: 7 | S15: 0.2 | T15: 0.94 | U15: 6.7 | V15: 6.9 | W15: 0.2 | X15: 1.36
B16: 0.8125 | C16: 1540 | D16: 70 | E16: 500 | F16: 2375 | G16: S | H16: 3.4 | I16: 90 | J16: 90 | K16: 90 | L16: 25.1 | M16: 6 | N16: ,,49 | O16: 16 | P16: 8.4 | Q16: 6.8 | R16: 9.3 | S16: 0.18 | T16: 0.92 | U16: 6.9 | V16: 8.7 | W16: 0.17 | X16: 1.23
B17: 0.89583333 | C17: 1600 | D17: 80 | E17: 500 | F17: 2364 | G17: S | H17: 3.11 | I17: 90 | J17: 90 | K17: 90 | L17: 24.9 | M17: 6.8 | N17: 3.58 | O17: 15 | P17: 10.6 | Q17: 6.8 | R17: 8.4 | S17: 0.31 | T17: 0.96 | U17: 6.8 | V17: 9.6 | W17: 0.2 | X17: 1.16
B18: 0.97916667 | C18: - | D18: - | E18: - | F18: - | G18: - | H18: - | I18: - | J18: - | K18: - | L18: - | M18: - | N18: - | O18: - | P18: - | Q18: - | R18: - | S18: - | T18: - | U18: - | V18: - | W18: - | X18: -
B19: 0.0625 | C19: 1150 | D19: 90 | E19: 500 | F19: 1822 | G19: S | H19: 3.4 | I19: 90 | J19: 90 | K19: 90 | L19: 24.5 | M19: 6.8 | N19: 3.61 | O19: 14 | P19: 7.3 | Q19: 6.9 | R19: 9.9 | S19: 0.17 | T19: 1.18 | U19: 6.9 | V19: 9 | W19: 0.16 | X19: 1.1
B20: 0.14583333 | C20: 1167 | D20: - | E20: 500 | F20: 1833 | G20: S | H20: 3.4 | I20: 90 | J20: 90 | K20: 90 | L20: 23.6 | M20: 6.8 | N20: 3.87 | O20: 16 | P20: 10.5 | Q20: 7 | R20: 10.7 | S20: 0.21 | T20: 0.83 | U20: 7 | V20: 10.6 | W20: 0.19 | X20: 0.83
B21: 0.22916667 | C21: 1156 | D21: - | E21: 500 | F21: 1830 | G21: S | H21: 3.4 | I21: 90 | J21: 90 | K21: 90 | L21: 23.3 | M21: 6.8 | N21: 3.76 | O21: 15 | P21: 9.9 | Q21: 6.9 | R21: 11.4 | S21: 0.21 | T21: 0.91 | U21: 7 | V21: 12.6 | W21: 0.29 | X21: 1.13
B23: OBSERVAÇÕES:

Sheet 19.04
B2: ETA BRASÍLIA | C2: VA
B3: ESTUDO EQUILÍBRIO QUÍMICO H20 COAGULADA
B4: LADOS PAR E ÍMAR
B5: DATA: | C5: 46131 | E5: TURNO I | F5: Cláudio Py / Leandro
E6: TURNO II | F6: Maciel / Mathias
B8: HORA | C8: Vazões H20 | G8: DOSAGENS | I8: FLOCULAÇÃO GRADIENTES | L8: LABORATÓRIO ETA-BRUTA COMPOSTA | Q8: FLOCULADOR / FLOTADOR PAR - N° 6 | U8: FLOCULADOR / FLOTADOR ÍMPAR - N° 5
C9: TOR (l/s) | D9: SM (l/s) | E9: BNN (l/s) | F9: TOTAL (l/s) | G9: CAL (s/n) | H9: PAC (mg/l) | I9: 1ª Camara | J9: 2ª Camara | K9: 3ª Camara | L9: TEMP (°c) | M9: PH | N9: TURB | O9: COR | P9: ALC. (mg/l) | Q9: PH | R9: ALC. (mg/l) | S9: TURB PAPEL FILTRO | T9: TURB. FLOT. CLP | U9: PH | V9: ALC. (mg/l) | W9: TURB PAPEL FILTRO | X9: TURB. FLOT. CLP
B10: 0.3125 | C10: 560 | D10: 87 | E10: 525 | F10: 1210 | G10: S | H10: 3.6 | I10: 1435 | J10: 1435 | K10: 1435 | L10: 23.6 | M10: 6.8 | N10: 4.27 | O10: 20 | P10: 9.2 | Q10: 6.9 | R10: 10.8 | S10: 0.18 | T10: 0.83 | U10: 6.9 | V10: 10.2 | W10: 0.13 | X10: 0.99
B11: 0.39583333 | C11: 530 | D11: 82 | E11: 528 | F11: 1166 | G11: S | H11: 3.6 | I11: 1435 | J11: 1435 | K11: 1435 | L11: 23.8 | M11: 6.8 | N11: 4.76 | O11: 17 | P11: 14.1 | Q11: 7 | R11: 15 | S11: 0.15 | T11: 0.77 | U11: 7 | V11: 10.5 | W11: 0.13 | X11: 0.84
B12: 0.47916667 | C12: 551 | D12: 82 | E12: 528 | F12: 1164 | G12: S | H12: 3.6 | I12: 1435 | J12: 1435 | K12: 1435 | L12: 24.2 | M12: 6.8 | N12: 3.85 | O12: 15 | P12: 12.2 | Q12: 6.9 | R12: 15 | S12: 0.18 | T12: 0.72 | U12: 6.9 | V12: 13.2 | W12: 0.19 | X12: 0.75
B13: 0.5625
B14: 0.64583333 | C14: 542 | D14: 89 | E14: 528 | F14: 1249 | G14: S | H14: 3.6 | I14: 1435 | J14: 1435 | K14: 1435 | L14: 26.1 | M14: 6.9 | N14: 4.41 | O14: 16 | P14: 9.8 | Q14: 6.9 | R14: 10.3 | S14: 0.36 | T14: 0.7 | U14: 7 | V14: 10.4 | W14: 0.34 | X14: 0.68
B15: 0.72916667 | C15: 1270 | D15: 82 | E15: 500 | F15: 1818 | G15: S | H15: 3.6 | I15: 1435 | J15: 1435 | L15: 25.5 | M15: 6.8 | N15: 4.2 | O15: 17 | P15: 4.7 | Q15: 6.7 | R15: 6.9 | S15: 0.28 | T15: 0.75 | U15: 6.7 | V15: 7.8 | W15: 0.15 | X15: 0.76
B16: 0.8125 | C16: 1234 | D16: 82 | E16: 500 | F16: 1814 | G16: S | H16: 3.6 | I16: 1435 | J16: 1435 | K16: 1435 | L16: 14.9 | M16: 6.7 | N16: 4.07 | O16: 16 | P16: 8 | Q16: 7.1 | R16: 6.8 | S16: 0.17 | T16: 0.66 | U16: 6.7 | V16: 7.5 | W16: 0.24 | X16: 0.75
B17: 0.89583333 | C17: 1159 | D17: 90 | E17: 498 | F17: 1821 | G17: S | H17: 3.6 | I17: 1435 | J17: 1435 | K17: 1435 | L17: 24.6 | M17: 6.8 | N17: 5.7 | O17: 19 | P17: 8.4 | Q17: 6.8 | R17: 8.1 | S17: 0.3 | T17: 0.65 | U17: 6.7 | V17: 7.9 | W17: 0.15 | X17: 1.27
B18: 0.97916667 | C18: 1148 | D18: 80 | E18: 500 | F18: 1826 | G18: S | H18: 3.6 | I18: 1435 | J18: 1435 | K18: 1435 | L18: 24 | M18: 6.8 | N18: 3.68 | O18: 15 | P18: 9.4 | Q18: 6.7 | R18: 8.8 | S18: 0.14 | T18: 0.6 | U18: 6.6 | V18: 8.3 | W18: 0.19 | X18: 0.75
B19: 0.0625 | C19: 1146 | D19: 88 | E19: 500 | F19: 1814 | G19: S | H19: 3.6 | I19: 1435 | J19: 1435 | K19: 1435 | L19: 24.1 | M19: 6.7 | N19: 4.57 | O19: 17 | P19: 7.2 | Q19: 6.7 | R19: 7.7 | S19: 0.22 | T19: 0.65 | U19: 6.6 | V19: 7.5 | W19: 0.21 | X19: 0.79
B20: 0.14583333 | C20: 1089 | D20: 87 | E20: 500 | F20: 1830 | G20: S | H20: 3.6 | I20: 1435 | J20: 1435 | K20: 1435 | L20: 24 | M20: 6.7 | N20: 6.79 | O20: 15 | P20: 9.2 | Q20: 6.7 | R20: 9.5 | S20: 0.18 | T20: 0.79 | U20: 6.6 | V20: 9.6 | W20: 0.21 | X20: 1
B21: 0.22916667 | C21: 1215 | D21: 86 | E21: 499 | F21: 1809 | G21: S | H21: 3.6 | I21: 1435 | J21: 1435 | K21: 1435 | L21: 23.5 | M21: 6.6 | N21: 3.65 | O21: 17 | P21: 8.1 | Q21: 6.7 | R21: 7.5 | S21: 0.15 | T21: 0.72 | U21: 6.7 | V21: 7.9 | W21: 0.19 | X21: 1.21
B23: OBSERVAÇÕES:

Sheet 18.04
B2: ETA BRASÍLIA | C2: VA
B3: ESTUDO EQUILÍBRIO QUÍMICO H20 COAGULADA
B4: LADOS PAR E ÍMAR
B5: DATA: | C5: 46130 | E5: TURNO I
E6: TURNO II
B7: MACIEL/MATHIAS
B8: HORA | C8: Vazões H20 | G8: DOSAGENS | I8: FLOCULAÇÃO GRADIENTES | L8: LABORATÓRIO ETA-BRUTA COMPOSTA | Q8: FLOCULADOR / FLOTADOR PAR - N° 6 | U8: FLOCULADOR / FLOTADOR ÍMPAR - N° 5
C9: TOR (l/s) | D9: SM (l/s) | E9: BNN (l/s) | F9: TOTAL (l/s) | G9: CAL (s/n) | H9: PAC (mg/l) | I9: 1ª Camara | J9: 2ª Camara | K9: 3ª Camara | L9: TEMP (°c) | M9: PH | N9: TURB | O9: COR | P9: ALC. (mg/l) | Q9: PH | R9: ALC. (mg/l) | S9: TURB PAPEL FILTRO | T9: TURB. FLOT. CLP | U9: PH | V9: ALC. (mg/l) | W9: TURB PAPEL FILTRO | X9: TURB. FLOT. CLP
B10: 0.3125 | C10: 1192 | D10: 80 | E10: 499 | F10: 1814 | G10: S | H10: 3.6 | I10: 1435 | J10: 1435 | K10: 1435 | L10: 23.3 | M10: 6.7 | N10: 4.06 | O10: 10 | P10: 8 | Q10: 6.7 | R10: 8.4 | S10: 0.17 | T10: 3.97 | U10: 6.6 | V10: 8.5 | W10: 0.17 | X10: 4.03
B11: 0.39583333 | C11: 1160 | D11: 81 | E11: 500 | F11: 1863 | G11: S | H11: 3.6 | I11: 1435 | J11: 1435 | K11: 1435 | L11: 23.3 | M11: 6.7 | N11: 4.1 | O11: 18 | P11: 9.2 | Q11: 6.7 | R11: 9.3 | S11: 0.11 | T11: 4.14 | U11: 6.7 | V11: 8.7 | W11: 0.15 | X11: 3.83
B12: 0.47916667 | C12: 1197 | D12: 82 | E12: 499 | F12: 1749 | G12: S | H12: 3.6 | I12: 1435 | J12: 1435 | K12: 1435 | L12: 24.3 | M12: 6.7 | N12: 4.66 | O12: 18 | P12: 8.2 | Q12: 6.7 | R12: 8.6 | S12: 0.25 | T12: 5.46 | U12: 6.6 | V12: 8.8 | W12: 0.36 | X12: 5.8
B13: 0.5625 | C13: * | D13: - | E13: - | F13: - | G13: - | H13: - | I13: - | J13: - | K13: - | L13: - | M13: - | N13: - | O13: - | P13: - | Q13: - | R13: - | S13: - | T13: - | U13: - | V13: - | W13: - | X13: -
B14: 0.64583333 | C14: 1060 | D14: 85 | E14: 499 | F14: 1743 | G14: S | H14: 3.6 | I14: 1435 | J14: 1435 | K14: 1435 | L14: 25 | M14: 6.7 | N14: 4.1 | O14: 16 | P14: 7.2 | Q14: 6.7 | R14: 6.7 | S14: 0.13 | T14: 4.13 | U14: 6.7 | V14: 7.1 | W14: 0.15 | X14: 3.98
B15: 0.72916667 | C15: 1173 | D15: 81 | E15: 500 | F15: 1781 | G15: S | H15: 3.6 | I15: 1435 | J15: 1435 | K15: 1435 | L15: 25 | M15: 6.7 | N15: 4.05 | O15: 15 | P15: 7.5 | Q15: 6.8 | R15: 6.9 | S15: 0.13 | T15: 4.17 | U15: 6.7 | V15: 7.2 | W15: 0.17 | X15: 4.05
B16: 0.8125 | C16: 1191 | D16: 81 | E16: 500 | F16: 1895 | G16: S | H16: 3.6 | I16: 1435 | J16: 1435 | K16: 1435 | L16: 25.1 | M16: 6.7 | N16: 3.99 | O16: 17 | P16: 9.2 | Q16: 6.7 | R16: 12 | S16: 0.12 | T16: 4.77 | U16: 6.8 | V16: 10 | W16: 0.1 | X16: 6.87
B17: 0.89583333 | C17: 1099 | D17: 81 | E17: 498 | F17: 1903 | G17: S | H17: 3.6 | I17: 1435 | J17: 1435 | K17: 1435 | L17: 24.7 | M17: 6.7 | N17: 4.46 | O17: 17 | P17: 7 | Q17: 6.8 | R17: 6.9 | S17: 0.17 | T17: 1.74 | U17: 6.8 | V17: 6.7 | W17: 0.18 | X17: 1.44
B18: 0.97916667 | C18: 1172 | D18: 88 | E18: 500 | F18: 1892 | G18: S | H18: 3.6 | I18: 1435 | J18: 1435 | K18: 1435 | L18: 24.3 | M18: 6.8 | N18: 4.39 | O18: 16 | P18: 7.1 | Q18: 6.7 | R18: 6.9 | S18: 0.15 | T18: 1.02 | U18: 6.7 | V18: 6.8 | W18: 0.14 | X18: 1.07
B19: 0.0625 | C19: 548 | D19: 85 | E19: 527 | F19: 1214 | G19: S | H19: 3.6 | I19: 1435 | J19: 1435 | K19: 1435 | L19: 23.8 | M19: 6.9 | N19: 3.96 | O19: 16 | P19: 9.9 | Q19: 6.9 | R19: 10.2 | S19: 0.17 | T19: 0.82 | U19: 6.9 | V19: 11 | W19: 0.18 | X19: 0.92
B20: 0.14583333 | C20: 544 | D20: 86 | E20: 528 | F20: 1215 | G20: S | H20: 3.6 | I20: 1435 | J20: 1435 | K20: 1435 | L20: 23.8 | M20: 6.8 | N20: 4.11 | O20: 16 | P20: 13.3 | Q20: 6.9 | R20: 11.8 | S20: 0.13 | T20: 0.84 | U20: 6.9 | V20: 15.4 | W20: 0.17 | X20: 0.89
B21: 0.22916667 | C21: 532 | D21: 82 | E21: 527 | F21: 1269 | G21: S | H21: 3.6 | I21: 1435 | J21: 1435 | K21: 1435 | L21: 23.8 | M21: 6.8 | N21: 4.33 | O21: 16 | P21: 6.1 | Q21: 6.9 | R21: 8.1 | S21: 0.26 | T21: 0.66 | U21: 7 | V21: 8.4 | W21: 0.16 | X21: 1.68
B23: OBSERVAÇÕES: | D23: *Intrajoranda

Sheet 17.04
B2: ETA BRASÍLIA | C2: VA
B3: ESTUDO EQUILÍBRIO QUÍMICO H20 COAGULADA
B4: LADOS PAR E ÍMAR
B5: DATA: | C5: 46129 | E5: TURNO I
E6: TURNO II
B8: HORA | C8: Vazões H20 | G8: DOSAGENS | I8: FLOCULAÇÃO GRADIENTES | L8: LABORATÓRIO ETA-BRUTA COMPOSTA | Q8: FLOCULADOR / FLOTADOR PAR - N° 6 | U8: FLOCULADOR / FLOTADOR ÍMPAR - N° 5
C9: TOR (l/s) | D9: SM (l/s) | E9: BNN (l/s) | F9: TOTAL (l/s) | G9: CAL (s/n) | H9: PAC (mg/l) | I9: 1ª Camara | J9: 2ª Camara | K9: 3ª Camara | L9: TEMP (°c) | M9: PH | N9: TURB | O9: COR | P9: ALC. (mg/l) | Q9: PH | R9: ALC. (mg/l) | S9: TURB PAPEL FILTRO | T9: TURB. FLOT. CLP | U9: PH | V9: ALC. (mg/l) | W9: TURB PAPEL FILTRO | X9: TURB. FLOT. CLP
B10: 0.3125 | C10: 1746 | D10: -
B11: 0.39583333 | C11: 1746 | D11: - | E11: 500 | F11: 2256 | G11: S | H11: 4.6 | I11: 1435 | J11: 1435 | K11: 1435 | L11: 24.7 | M11: 6.7 | N11: 5.21 | O11: 16 | P11: 6.2 | Q11: 6.7 | R11: 5.6 | S11: 0.29 | T11: 2.24 | U11: 6.8 | V11: 6 | W11: 0.28 | X11: 1.37
B12: 0.47916667 | C12: 1528 | D12: - | E12: 499 | F12: 2257 | G12: S | H12: 4.6 | I12: 1435 | J12: 1435 | K12: 1435 | L12: 23.8 | M12: 6.7 | N12: 4.49 | O12: 16 | P12: 6.4 | Q12: 6.8 | R12: 6.4 | S12: 0.29 | T12: 1.95 | U12: 6.7 | V12: 6.6 | W12: 0.21 | X12: 1.25
B13: 0.5625 | C13: 1621 | D13: - | E13: 501 | F13: 2243 | G13: S | H13: 4.6 | I13: 1435 | J13: 1435 | K13: 1435 | L13: 24.1 | M13: 6.7 | N13: 4.29 | O13: 16 | P13: 6.6 | Q13: 6.8 | R13: 6.2 | S13: 0.37 | T13: 1.94 | U13: 6.7 | V13: 6.1 | W13: 0.21 | X13: 1.09
B14: 0.64583333 | C14: 1510 | D14: - | E14: 499 | F14: 2220 | G14: S | H14: 4 | I14: 1435 | J14: 1435 | K14: 1435 | L14: 24.6 | M14: 6.7 | N14: 3.97 | O14: 15 | P14: 6 | Q14: 6.8 | R14: 5.9 | S14: 0.26 | T14: 1.59 | U14: 6.8 | V14: 6 | W14: 0.12 | X14: 0.95
B15: 0.72916667 | C15: 1770 | D15: - | E15: 500 | F15: 2330 | G15: S | H15: 4 | I15: 1435 | J15: 1435 | K15: 1435 | L15: 25 | M15: 6.7 | N15: 4.54 | O15: 15 | P15: 5.9 | Q15: 6.8 | R15: 6.1 | S15: 0.49 | T15: 0.74 | U15: 6.7 | V15: 5.8 | W15: 0.19 | X15: 1.83
B16: 0.8125 | C16: 1140 | D16: - | E16: 500 | F16: 1884 | G16: S | H16: 4 | I16: 1435 | J16: 1435 | K16: 1435 | L16: 24.7 | M16: 6.7 | N16: 4.45 | O16: 16 | P16: 5.1 | Q16: 6.6 | R16: 5.4 | S16: 0.12 | T16: 0.44 | U16: 6.7 | V16: 5.3 | W16: 0.15 | X16: 1.8
B17: 0.89583333 | C17: 1114 | D17: - | E17: 500 | F17: 1887 | G17: S | H17: 4 | I17: 1435 | J17: 1435 | K17: 1435 | L17: 24.5 | M17: 6.7 | N17: 4.31 | O17: 22 | P17: 6.6 | Q17: 6.8 | R17: 6.5 | S17: 0.19 | T17: 0.45 | U17: 6.7 | V17: 6.3 | W17: 0.13 | X17: 1.99
B18: 0.97916667 | C18: 1083 | D18: - | E18: 500 | F18: 1888 | G18: S | H18: 4 | I18: 1435 | J18: 1435 | K18: 1435 | L18: 24 | M18: 6.7 | N18: 4.34 | O18: 22 | P18: 6.5 | Q18: 6.8 | R18: 9 | S18: 0.12 | T18: 0.48 | U18: 6.7 | V18: 7.5 | W18: 0.2 | X18: 1.02
B19: 0.0625 | C19: 1123 | D19: - | E19: 500 | F19: 1887 | G19: S | H19: 4 | I19: 1435 | J19: 1435 | K19: 1435 | L19: 24 | M19: 6.7 | N19: 4.83 | O19: 20 | P19: 6.6 | Q19: 6.8 | R19: 7.7 | S19: 0.09 | T19: 0.49 | U19: 6.7 | V19: 9.7 | W19: 0.08 | X19: 1.54
B20: 0.14583333 | C20: 1088 | D20: - | E20: 498.7 | F20: 1889 | G20: S | H20: 4 | I20: 1435 | J20: 1435 | K20: 1435 | L20: 23.8 | M20: 6.7 | N20: 4.6 | O20: 10 | P20: 6.2 | Q20: 6.8 | R20: 5.7 | S20: 0.09 | T20: 0.5 | U20: 6.7 | V20: 7.1 | W20: 0.07 | X20: 0.78
B21: 0.22916667 | C21: 1200 | D21: - | E21: 499.3 | F21: 1889 | G21: S | H21: 3.6 | I21: 1435 | J21: 1435 | K21: 1435 | L21: 23.2 | M21: 6.7 | N21: 4.02 | O21: 8 | P21: 6.2 | Q21: 6.7 | R21: 5.9 | S21: 0.15 | T21: 0.52 | U21: 6.7 | V21: 6.6 | W21: 0.15 | X21: 0.82
B23: OBSERVAÇÕES:

Sheet 16.04
B2: ETA BRASÍLIA | C2: VA
B3: ESTUDO EQUILÍBRIO QUÍMICO H20 COAGULADA
B4: LADOS PAR E ÍMAR
B5: DATA: | C5: 46128 | E5: TURNO I
E6: TURNO II
B8: HORA | C8: Vazões H20 | G8: DOSAGENS | I8: FLOCULAÇÃO GRADIENTES | L8: LABORATÓRIO ETA-BRUTA COMPOSTA | Q8: FLOCULADOR / FLOTADOR PAR - N° 4 | U8: FLOCULADOR / FLOTADOR ÍMPAR - N° 3
C9: TOR (l/s) | D9: SM (l/s) | E9: BNN (l/s) | F9: TOTAL (l/s) | G9: CAL (s/n) | H9: PAC (mg/l) | I9: 1ª Camara | J9: 2ª Camara | K9: 3ª Camara | L9: TEMP (°c) | M9: PH | N9: TURB | O9: COR | P9: ALC. (mg/l) | Q9: PH | R9: ALC. (mg/l) | S9: TURB PAPEL FILTRO | T9: TURB. FLOT. CLP | U9: PH | V9: ALC. (mg/l) | W9: TURB PAPEL FILTRO | X9: TURB. FLOT. CLP
B10: 0.35416667 | G10: S
B11: 0.39583333 | C11: 1180 | D11: 80 | E11: 500 | F11: 1874 | G11: S | H11: 4.7 | L11: 23.8 | M11: 6.8 | N11: 4.48 | O11: 20 | P11: 6.4 | Q11: 6.9 | R11: 7.3 | S11: 0.12 | U11: 6.8 | V11: 7.8 | W11: 0.2
B12: 0.4375 | C12: 1154 | D12: 84 | E12: 500 | F12: 1871 | G12: S | H12: 4.6 | L12: 23.8 | M12: 6.7 | N12: 4.94 | O12: 16 | P12: 8.9 | Q12: 6.7 | R12: 8.1 | S12: 0.1 | U12: 6.7 | V12: 8.4 | W12: 0.29
B13: 0.47916667 | C13: 1130 | D13: 83 | E13: 500 | F13: 1888 | G13: S | H13: 4.5 | L13: 24 | M13: 6.7 | N13: 4.05 | O13: 18 | P13: 6.9 | Q13: 6.8 | R13: 9.4 | S13: 0.11 | U13: 6.7 | V13: 9.4 | W13: 0.27
B14: 0.52083333 | C14: * | D14: * | E14: * | F14: * | G14: * | H14: * | I14: * | J14: * | K14: * | L14: * | M14: * | N14: * | O14: * | P14: * | Q14: * | R14: * | S14: * | T14: * | U14: * | V14: * | W14: * | X14: *
B15: 0.5625 | C15: * | D15: * | E15: * | F15: * | G15: * | H15: * | I15: * | J15: * | K15: * | L15: * | M15: * | N15: * | O15: * | P15: * | Q15: * | R15: * | S15: * | T15: * | U15: * | V15: * | W15: * | X15: *
B16: 0.60416667 | C16: 1139 | D16: 84 | E16: 499 | F16: 1785 | G16: S | H16: 4.4 | L16: 24 | M16: 6.8 | N16: 5.66 | O16: 21 | P16: 8.7 | Q16: 6.8 | R16: 7.2 | S16: 0.17 | U16: 6.8 | V16: 8.2 | W16: 0.25
B17: 0.64583333 | C17: ** | D17: ** | E17: ** | F17: ** | G17: ** | H17: ** | I17: ** | J17: ** | K17: ** | L17: ** | M17: ** | N17: ** | O17: ** | P17: ** | Q17: ** | R17: ** | S17: ** | T17: ** | U17: ** | V17: ** | W17: ** | X17: **
B18: 0.6875 | C18: 1239 | D18: 81 | E18: 500 | F18: 1845 | G18: S | H18: 4.4 | L18: 24.6 | M18: 6.8 | N18: 7.04 | O18: 15 | P18: 8.8 | Q18: 6.8 | R18: 8.3 | S18: 0.18 | U18: 6.7 | V18: 8.4 | W18: 0.25
B19: 0.72916667 | C19: 1212 | D19: 70 | E19: 500 | F19: 1876 | G19: S | H19: 4.4 | L19: 24.4 | M19: 6.7 | N19: 3.36 | O19: 18 | P19: 8.4 | Q19: 6.7 | R19: 8.1 | S19: 0.12 | U19: 6.6 | V19: 8.8 | W19: 0.19
B20: 0.77083333 | C20: - | D20: - | E20: - | F20: - | G20: - | H20: - | I20: - | J20: - | K20: - | L20: - | M20: - | N20: - | O20: - | P20: - | Q20: - | R20: - | S20: - | T20: - | U20: - | V20: - | W20: - | X20: -
B21: 0.8125 | C21: 1173 | D21: 82 | E21: 499 | F21: 1884 | G21: S | H21: 4.4 | L21: 24.6 | M21: 6.8 | N21: 3.85 | O21: 15 | P21: 9.7 | Q21: 7 | R21: 9.6 | S21: 0.12 | U21: 7 | V21: 8.8 | W21: 0.11
B22: 0.85416667 | C22: 1183 | D22: 82 | E22: 499 | F22: 1809 | G22: S | H22: 4.4 | L22: 24.7 | M22: 6.8 | N22: 3.4 | O22: 14 | P22: 10 | Q22: 7 | R22: 9.1 | S22: 0.12 | U22: 6.9 | V22: 8.3 | W22: 0.16
B24: OBSERVAÇÕES: | D24: * Intrajoranda
D25: ** ETA DESATIVADA

Sheet EQUILIBRIO QUIMICO COM CARGA
A1: DATA | B1: HORA | C1: VAZÃO ÁGUA BRUTA TOR (L/s) | D1: VAZÃO ÁGUA BRUTA SM (L/s) | E1: VAZÃO ÁGUA BRUTA BNN (L/s) | F1: VAZÃO ÁGUA BRUTA TOTAL (L/s) | G1: DOS CAL (s/n) | H1: DOS PAC (mg/L) | I1: CARGA (CSV) | J1: FLOC GRAD 1ª Câmara | K1: FLOC GRAD 2ª Câmara | L1: FLOC GRAD 3ª Câmara | M1: ÁGUA BRUTA TEMP (°C) | N1: ÁGUA BRUTA pH | O1: ÁGUA BRUTA TURB (uT) | P1: ÁGUA BRUTA COR (uC) | Q1: ÁGUA BRUTA ALC. (mg/L) | R1: ÁGUA FILTRADA TURB (uT) | S1: Sa (SOLUBILIDADE DO AR NA ÁGUA A 25ºC) | T1: Pa (PRESSÃO ATMOSFÉRICA - DF) | U1: f (TAXA DE EFICIÊNCIA DO SATURADOR) | V1: LADO PAR SST_coag (CONCENTRAÇÃO DE SÓLIDOS SUSPENSOS TOTAIS (mg/L) | W1: LADO PAR Car(CONCENTRAÇÃO DE AR DISPONÍVEL NA ZONA DE MISTURA (mg/L)) | X1: LADO PAR A/S (RELAÇÃO MASSA DE AR / MASSA DE SST | Y1: LADO PAR Nº FLOC. | Z1: LADO PAR Nº FLOT. | AA1: LADO PAR FLOTAÇÃO Pressão Sat. (bar) | AB1: LADO PAR FLOTAÇÃO Vazão Rec.(L/s) | AC1: LADO PAR ÁGUA COAGULADA pH | AD1: LADO PAR ÁGUA COAGULADA ALC. (mg/L) | AE1: LADO PAR ÁGUA COAGULADA TURB PAPEL FILTRO (uT) | AF1: LADO PAR FLOTAÇÃO TURB CLARIFICADA CLP (uT) | AG1: LADO ÍMPAR SST_coag (CONCENTRAÇÃO DE SÓLIDOS SUSPENSOS TOTAIS (mg/L) | AH1: LADO ÍMPAR Car(CONCENTRAÇÃO DE AR DISPONÍVEL NA ZONA DE MISTURA (mg/L)) | AI1: LADO ÍMPAR A/S (RELAÇÃO MASSA DE AR / MASSA DE SST | AJ1: LADO ÍMPAR Nº FLOC. | AK1: LADO ÍMPAR Nº FLOT. | AL1: LADO ÍMPAR FLOTAÇÃO Pressão Sat. (bar) | AM1: LADO ÍMPAR FLOTAÇÃO Vazão Rec.(L/s) | AN1: LADO ÍMPAR ÁGUA COAGULADA pH | AO1: LADO ÍMPAR ÁGUA COAGULADA ALC. (mg/l) | AP1: LADO ÍMPAR ÁGUA COAGULADA TURB PAPEL FILTRO (uT) | AQ1: LADO ÍMPAR FLOTAÇÃO TURB CLARIFICADA CLP (uT) | AR1: Q_TOTAL | AS1: %TOR | AT1: %SM | AU1: %BNN | AV1: TAXA_RECIR. _PAR | AW1: TAXA_RECIR. _ÍMPAR | AX1: TAXA_REMOÇÃO_ÍMPAR | AY1: TAXA_REMOÇÃO_PAR | AZ1: FAIXA_ALC_BRUTA | BA1: FAIXA_COR_BRUTA | BB1: FAIXA_TURB_BRUTA | BC1: TIPO_AGUA_BRUTA | BD1: FAIXA_TURB_PAPEL_FILTRO_PAR | BE1: FAIXA_TURB_PAPEL_FILTRO_ÍMPAR | BF1: FAIXA_TURB_CLAR_PAR | BG1: FAIXA_TURB_CLAR_ÍMPAR | BH1: FAIXA_TURB_FILT
A2: 46259 | B2: 0.39583333 | C2: 350 | D2: 1700 | E2: 0 | F2: 2200 | G2: N | H2: 9.8 | I2: -38 | J2: 90 | K2: 90 | L2: 90 | M2: 25 | N2: 6.4 | O2: 1.06 | P2: 8 | Q2: 5.8 | R2: 0.17 | S2: 22.36 | T2: 0.88 | U2: 0.7 | V2: =(O2+0.3*H2+2)*(F2/2/Z2) -> 1650 | W2: =S2*(U2*AA2*0.987-T2)*AB2 -> 1372.5563 | X2: =W2/V2 -> 0.8318523 | Y2: 3 | Z2: 4 | AA2: 6.5 | AB2: 17 | AC2: 5.6 | AD2: 2 | AE2: 0.86 | AF2: 0.14 | AG2: =(O2+0.3*H2+2)*(F2/2/AK2) -> 1650 | AH2: =S2*(U2*AL2*0.987-T2)*AM2 -> 1768.1589 | AI2: =AH2/AG2 -> 1.0716115 | AJ2: 4 | AK2: 4 | AL2: 6.25 | AM2: 23 | AN2: 5.2 | AO2: 2.2 | AP2: 1.21 | AQ2: 0.11 | AR2: =SUM(C2:E2) -> 2050 | AS2: =C2/AR2 -> 0.17073171 | AT2: =D2/AR2 -> 0.82926829 | AU2: =E2/AR2 -> 0 | AV2: =IF(AND(F2<>"",Z2<>""),AB2/(F2/2/Z2),"") -> 0.061818182 | AW2: =IF(AND(F2<>"",AK2<>""),AM2/(F2/2/AK2),"") -> 0.083636364 | AX2: =IF(AND(AQ2<>"",1-(AQ2/O2)>0),1-(AQ2/O2),"") -> 0.89622642 | AY2: =IF(AND(AF2<>"",1-(AF2/O2)>0),1-(AF2/O2),"") -> 0.86792453 | AZ2: =IF(Q2="","",IF(Q2<2.5,"Alc. Bruta < 2,5 mg/L",IF(Q2<5,"2,5 ≤ Alc. Bruta < 5,0 mg/L",IF(Q2<7.5,"5,0 ≤ Alc. Bruta < 7,5 mg/L",IF(Q2<10,"7,5 ≤ Alc. Bruta < 10,0 mg/L",IF(Q2<15,"10,0 ≤ Alca. Bruta < 15,0 mg/L","Alc. Bruta > 15 mg/L")))))) -> 5,0 ≤ Alc. Bruta < 7,5 mg/L | BA2: =IF(P2="","",IF(P2<5,"Cor <5 uC",IF(P2<10,"5 ≤ Cor < 10 uC",IF(P2<15,"10 ≤ Cor <15 uC",IF(P2<30,"15 ≤ Cor < 30 uC",IF(P2<50,"30 ≤ Cor < 50 uC","Cor > 50 uC")))))) -> 5 ≤ Cor < 10 uC | BB2: =IF(O2="","",IF(O2<2.5,"Turbidez < 2,5 uT",IF(O2<5,"2,5 ≤ Turb < 5,0 uT",IF(O2<7.5,"5,0 ≤ Turb < 7,5 uT",IF(O2<10,"7,5 ≤ Turb < 10,0 uT",IF(O2<15,"10,0 ≤ Turb < 15,0 uT","Turb > 15 uT")))))) -> Turbidez < 2,5 uT | BC2: =IF(AND(C2>D2,D2>E2),"TOR > SM > BNN",IF(AND(C2>E2,E2>D2),"TOR > BNN > SM",IF(AND(D2>C2,C2>E2),"SM > TOR > BNN",IF(AND(D2>E2,E2>C2),"SM > BNN > TOR",IF(AND(C2=D2,D2=E2),"TOR = SM = BNN","Comb. diferentes"))))) -> SM > TOR > BNN | BD2: =IF(OR(AE2="",AQ2="-"),"",IF(AE2<=0.25,"Tipo 1 (≤0,25) uT",IF(AE2<=0.5,"Tipo 2 (0,25-0,50) uT",IF(AE2<=0.75,"Tipo 3 (0,50-0,75) uT","Tipo 4 (>0,75) uT")))) -> Tipo 4 (>0,75) uT | BE2: =IF(OR(AP2="",AZ2="-"),"",IF(AP2<=0.25,"Tipo 1 (≤0,25) uT",IF(AP2<=0.5,"Tipo 2 (0,25-0,50) uT",IF(AP2<=0.75,"Tipo 3 (0,50-0,75) uT","Tipo 4 (>0,75) uT")))) -> Tipo 4 (>0,75) uT | BF2: =IF(OR(AF2="",AQ2="-"),"",IF(AF2<=0.25,"Tipo 1 (≤0,25) uT",IF(AF2<=0.5,"Tipo 2 (0,25-0,50) uT",IF(AF2<=0.75,"Tipo 3 (0,50-0,75) uT","Tipo 4 (>0,75) uT")))) -> Tipo 1 (≤0,25) uT | BG2: =IF(OR(AQ2="",AQ2="-"),"",IF(AQ2<=0.25,"Tipo 1 (≤0,25) uT",IF(AQ2<=0.5,"Tipo 2 (0,25-0,50) uT",IF(AQ2<=0.75,"Tipo 3 (0,50-0,75) uT","Tipo 4 (>0,75) uT")))) -> Tipo 1 (≤0,25) uT | BH2: =IF(OR(R2="",R2="-"),"",IF(R2<=0.25,"Tipo 1 (≤0,25) uT",IF(R2<=0.5,"Tipo 2 (0,25-0,50) uT",IF(R2<=0.75,"Tipo 3 (0,50-0,75) uT","Tipo 4 (>0,75) uT")))) -> Tipo 1 (≤0,25) uT
A3: 46259 | B3: 0.47916667 | C3: 362 | D3: 1691 | E3: 0 | F3: 2180 | G3: N | H3: 9.8 | I3: -92 | J3: 90 | K3: 90 | L3: 90 | M3: 25.4 | N3: 6.4 | O3: 0.9 | P3: 7 | Q3: 5 | R3: 0.24 | S3: 22.36 | T3: 0.88 | U3: 0.7 | V3: =(O3+0.3*H3+2)*(F3/2/Z3) -> 1591.4 | W3: =S3*(U3*AA3*0.987-T3)*AB3 -> 1372.5563 | X3: =W3/V3 -> 0.86248354 | Y3: 3 | Z3: 4 | AA3: 6.5 | AB3: 17 | AC3: 5.7 | AD3: 2.1 | AE3: 1.46 | AF3: 0.13 | AG3: =(O3+0.3*H3+2)*(F3/2/AK3) -> 1591.4 | AH3: =S3*(U3*AL3*0.987-T3)*AM3 -> 1785.9247 | AI3: =AH3/AG3 -> 1.122235 | AJ3: 4 | AK3: 4 | AL3: 6.3 | AM3: 23 | AN3: 5.3 | AO3: 2.2 | AP3: 1.25 | AQ3: 0.11 | AR3: =SUM(C3:E3) -> 2053 | AS3: =C3/AR3 -> 0.17632733 | AT3: =D3/AR3 -> 0.82367267 | AU3: =E3/AR3 -> 0 | AV3: =IF(AND(F3<>"",Z3<>""),AB3/(F3/2/Z3),"") -> 0.062385321 | AW3: =IF(AND(F3<>"",AK3<>""),AM3/(F3/2/AK3),"") -> 0.08440367 | AX3: =IF(AND(AQ3<>"",1-(AQ3/O3)>0),1-(AQ3/O3),"") -> 0.87777778 | AY3: =IF(AND(AF3<>"",1-(AF3/O3)>0),1-(AF3/O3),"") -> 0.85555556 | AZ3: =IF(Q3="","",IF(Q3<2.5,"Alc. Bruta < 2,5 mg/L",IF(Q3<5,"2,5 ≤ Alc. Bruta < 5,0 mg/L",IF(Q3<7.5,"5,0 ≤ Alc. Bruta < 7,5 mg/L",IF(Q3<10,"7,5 ≤ Alc. Bruta < 10,0 mg/L",IF(Q3<15,"10,0 ≤ Alca. Bruta < 15,0 mg/L","Alc. Bruta > 15 mg/L")))))) -> 5,0 ≤ Alc. Bruta < 7,5 mg/L | BA3: =IF(P3="","",IF(P3<5,"Cor <5 uC",IF(P3<10,"5 ≤ Cor < 10 uC",IF(P3<15,"10 ≤ Cor <15 uC",IF(P3<30,"15 ≤ Cor < 30 uC",IF(P3<50,"30 ≤ Cor < 50 uC","Cor > 50 uC")))))) -> 5 ≤ Cor < 10 uC | BB3: =IF(O3="","",IF(O3<2.5,"Turbidez < 2,5 uT",IF(O3<5,"2,5 ≤ Turb < 5,0 uT",IF(O3<7.5,"5,0 ≤ Turb < 7,5 uT",IF(O3<10,"7,5 ≤ Turb < 10,0 uT",IF(O3<15,"10,0 ≤ Turb < 15,0 uT","Turb > 15 uT")))))) -> Turbidez < 2,5 uT | BC3: =IF(AND(C3>D3,D3>E3),"TOR > SM > BNN",IF(AND(C3>E3,E3>D3),"TOR > BNN > SM",IF(AND(D3>C3,C3>E3),"SM > TOR > BNN",IF(AND(D3>E3,E3>C3),"SM > BNN > TOR",IF(AND(C3=D3,D3=E3),"TOR = SM = BNN","Comb. diferentes"))))) -> SM > TOR > BNN | BD3: =IF(OR(AE3="",AQ3="-"),"",IF(AE3<=0.25,"Tipo 1 (≤0,25) uT",IF(AE3<=0.5,"Tipo 2 (0,25-0,50) uT",IF(AE3<=0.75,"Tipo 3 (0,50-0,75) uT","Tipo 4 (>0,75) uT")))) -> Tipo 4 (>0,75) uT | BE3: =IF(OR(AP3="",AZ3="-"),"",IF(AP3<=0.25,"Tipo 1 (≤0,25) uT",IF(AP3<=0.5,"Tipo 2 (0,25-0,50) uT",IF(AP3<=0.75,"Tipo 3 (0,50-0,75) uT","Tipo 4 (>0,75) uT")))) -> Tipo 4 (>0,75) uT | BF3: =IF(OR(AF3="",AQ3="-"),"",IF(AF3<=0.25,"Tipo 1 (≤0,25) uT",IF(AF3<=0.5,"Tipo 2 (0,25-0,50) uT",IF(AF3<=0.75,"Tipo 3 (0,50-0,75) uT","Tipo 4 (>0,75) uT")))) -> Tipo 1 (≤0,25) uT | BG3: =IF(OR(AQ3="",AQ3="-"),"",IF(AQ3<=0.25,"Tipo 1 (≤0,25) uT",IF(AQ3<=0.5,"Tipo 2 (0,25-0,50) uT",IF(AQ3<=0.75,"Tipo 3 (0,50-0,75) uT","Tipo 4 (>0,75) uT")))) -> Tipo 1 (≤0,25) uT | BH3: =IF(OR(R3="",R3="-"),"",IF(R3<=0.25,"Tipo 1 (≤0,25) uT",IF(R3<=0.5,"Tipo 2 (0,25-0,50) uT",IF(R3<=0.75,"Tipo 3 (0,50-0,75) uT","Tipo 4 (>0,75) uT")))) -> Tipo 1 (≤0,25) uT
A4: 46259 | B4: 0.72916667 | C4: 344 | D4: 1544 | E4: 350 | F4: 2280 | G4: N | H4: 9.8 | I4: -118 | J4: 90 | K4: 90 | L4: 90 | M4: 26.6 | N4: 6.5 | O4: 0.98 | P4: 9 | Q4: 6.3 | R4: 0.29 | S4: 22.36 | T4: 0.88 | U4: 0.7 | V4: =(O4+0.3*H4+2)*(F4/2/Z4) -> 1687.2 | W4: =S4*(U4*AA4*0.987-T4)*AB4 -> 1380.435 | X4: =W4/V4 -> 0.81818104 | Y4: 3 | Z4: 4 | AA4: 6.53 | AB4: 17 | AC4: 6.1 | AD4: 4.9 | AE4: 0.69 | AF4: 0.18 | AG4: =(O4+0.3*H4+2)*(F4/2/AK4) -> 1687.2 | AH4: =S4*(U4*AL4*0.987-T4)*AM4 -> 1771.7121 | AI4: =AH4/AG4 -> 1.0500901 | AJ4: 3 | AK4: 4 | AL4: 6.26 | AM4: 23 | AN4: 6.1 | AO4: 4.4 | AP4: 0.7 | AQ4: 0.22 | AR4: =SUM(C4:E4) -> 2238 | AS4: =C4/AR4 -> 0.15370867 | AT4: =D4/AR4 -> 0.6899017 | AU4: =E4/AR4 -> 0.15638963 | AV4: =IF(AND(F4<>"",Z4<>""),AB4/(F4/2/Z4),"") -> 0.059649123 | AW4: =IF(AND(F4<>"",AK4<>""),AM4/(F4/2/AK4),"") -> 0.080701754 | AX4: =IF(AND(AQ4<>"",1-(AQ4/O4)>0),1-(AQ4/O4),"") -> 0.7755102 | AY4: =IF(AND(AF4<>"",1-(AF4/O4)>0),1-(AF4/O4),"") -> 0.81632653 | AZ4: =IF(Q4="","",IF(Q4<2.5,"Alc. Bruta < 2,5 mg/L",IF(Q4<5,"2,5 ≤ Alc. Bruta < 5,0 mg/L",IF(Q4<7.5,"5,0 ≤ Alc. Bruta < 7,5 mg/L",IF(Q4<10,"7,5 ≤ Alc. Bruta < 10,0 mg/L",IF(Q4<15,"10,0 ≤ Alca. Bruta < 15,0 mg/L","Alc. Bruta > 15 mg/L")))))) -> 5,0 ≤ Alc. Bruta < 7,5 mg/L | BA4: =IF(P4="","",IF(P4<5,"Cor <5 uC",IF(P4<10,"5 ≤ Cor < 10 uC",IF(P4<15,"10 ≤ Cor <15 uC",IF(P4<30,"15 ≤ Cor < 30 uC",IF(P4<50,"30 ≤ Cor < 50 uC","Cor > 50 uC")))))) -> 5 ≤ Cor < 10 uC | BB4: =IF(O4="","",IF(O4<2.5,"Turbidez < 2,5 uT",IF(O4<5,"2,5 ≤ Turb < 5,0 uT",IF(O4<7.5,"5,0 ≤ Turb < 7,5 uT",IF(O4<10,"7,5 ≤ Turb < 10,0 uT",IF(O4<15,"10,0 ≤ Turb < 15,0 uT","Turb > 15 uT")))))) -> Turbidez < 2,5 uT | BC4: =IF(AND(C4>D4,D4>E4),"TOR > SM > BNN",IF(AND(C4>E4,E4>D4),"TOR > BNN > SM",IF(AND(D4>C4,C4>E4),"SM > TOR > BNN",IF(AND(D4>E4,E4>C4),"SM > BNN > TOR",IF(AND(C4=D4,D4=E4),"TOR = SM = BNN","Comb. diferentes"))))) -> SM > BNN > TOR | BD4: =IF(OR(AE4="",AQ4="-"),"",IF(AE4<=0.25,"Tipo 1 (≤0,25) uT",IF(AE4<=0.5,"Tipo 2 (0,25-0,50) uT",IF(AE4<=0.75,"Tipo 3 (0,50-0,75) uT","Tipo 4 (>0,75) uT")))) -> Tipo 3 (0,50-0,75) uT | BE4: =IF(OR(AP4="",AZ4="-"),"",IF(AP4<=0.25,"Tipo 1 (≤0,25) uT",IF(AP4<=0.5,"Tipo 2 (0,25-0,50) uT",IF(AP4<=0.75,"Tipo 3 (0,50-0,75) uT","Tipo 4 (>0,75) uT")))) -> Tipo 3 (0,50-0,75) uT | BF4: =IF(OR(AF4="",AQ4="-"),"",IF(AF4<=0.25,"Tipo 1 (≤0,25) uT",IF(AF4<=0.5,"Tipo 2 (0,25-0,50) uT",IF(AF4<=0.75,"Tipo 3 (0,50-0,75) uT","Tipo 4 (>0,75) uT")))) -> Tipo 1 (≤0,25) uT | BG4: =IF(OR(AQ4="",AQ4="-"),"",IF(AQ4<=0.25,"Tipo 1 (≤0,25) uT",IF(AQ4<=0.5,"Tipo 2 (0,25-0,50) uT",IF(AQ4<=0.75,"Tipo 3 (0,50-0,75) uT","Tipo 4 (>0,75) uT")))) -> Tipo 1 (≤0,25) uT | BH4: =IF(OR(R4="",R4="-"),"",IF(R4<=0.25,"Tipo 1 (≤0,25) uT",IF(R4<=0.5,"Tipo 2 (0,25-0,50) uT",IF(R4<=0.75,"Tipo 3 (0,50-0,75) uT","Tipo 4 (>0,75) uT")))) -> Tipo 2 (0,25-0,50) uT
A5: 46259 | B5: 0.8125 | C5: 349 | D5: 1572 | E5: 350 | F5: 2214 | G5: N | H5: 9.8 | I5: -135 | J5: 90 | K5: 90 | L5: 90 | M5: 25.5 | N5: 6.6 | O5: 1.09 | P5: 11 | Q5: 6.3 | R5: 0.4 | S5: 22.36 | T5: 0.88 | U5: 0.7 | V5: =(O5+0.3*H5+2)*(F5/2/Z5) -> 1668.8025 | W5: =S5*(U5*AA5*0.987-T5)*AB5 -> 1390.94 | X5: =W5/V5 -> 0.8334959 | Y5: 3 | Z5: 4 | AA5: 6.57 | AB5: 17 | AC5: 6.2 | AD5: 5.2 | AE5: 0.51 | AF5: 0.2 | AG5: =(O5+0.3*H5+2)*(F5/2/AK5) -> 1668.8025 | AH5: =S5*(U5*AL5*0.987-T5)*AM5 -> 1768.1589 | AI5: =AH5/AG5 -> 1.0595376 | AJ5: 3 | AK5: 4 | AL5: 6.25 | AM5: 23 | AN5: 6.2 | AO5: 4.7 | AP5: 0.45 | AQ5: 0.22 | AR5: =SUM(C5:E5) -> 2271 | AS5: =C5/AR5 -> 0.15367679 | AT5: =D5/AR5 -> 0.69220608 | AU5: =E5/AR5 -> 0.15411713 | AV5: =IF(AND(F5<>"",Z5<>""),AB5/(F5/2/Z5),"") -> 0.061427281 | AW5: =IF(AND(F5<>"",AK5<>""),AM5/(F5/2/AK5),"") -> 0.083107498 | AX5: =IF(AND(AQ5<>"",1-(AQ5/O5)>0),1-(AQ5/O5),"") -> 0.79816514 | AY5: =IF(AND(AF5<>"",1-(AF5/O5)>0),1-(AF5/O5),"") -> 0.81651376 | AZ5: =IF(Q5="","",IF(Q5<2.5,"Alc. Bruta < 2,5 mg/L",IF(Q5<5,"2,5 ≤ Alc. Bruta < 5,0 mg/L",IF(Q5<7.5,"5,0 ≤ Alc. Bruta < 7,5 mg/L",IF(Q5<10,"7,5 ≤ Alc. Bruta < 10,0 mg/L",IF(Q5<15,"10,0 ≤ Alca. Bruta < 15,0 mg/L","Alc. Bruta > 15 mg/L")))))) -> 5,0 ≤ Alc. Bruta < 7,5 mg/L | BA5: =IF(P5="","",IF(P5<5,"Cor <5 uC",IF(P5<10,"5 ≤ Cor < 10 uC",IF(P5<15,"10 ≤ Cor <15 uC",IF(P5<30,"15 ≤ Cor < 30 uC",IF(P5<50,"30 ≤ Cor < 50 uC","Cor > 50 uC")))))) -> 10 ≤ Cor <15 uC | BB5: =IF(O5="","",IF(O5<2.5,"Turbidez < 2,5 uT",IF(O5<5,"2,5 ≤ Turb < 5,0 uT",IF(O5<7.5,"5,0 ≤ Turb < 7,5 uT",IF(O5<10,"7,5 ≤ Turb < 10,0 uT",IF(O5<15,"10,0 ≤ Turb < 15,0 uT","Turb > 15 uT")))))) -> Turbidez < 2,5 uT | BC5: =IF(AND(C5>D5,D5>E5),"TOR > SM > BNN",IF(AND(C5>E5,E5>D5),"TOR > BNN > SM",IF(AND(D5>C5,C5>E5),"SM > TOR > BNN",IF(AND(D5>E5,E5>C5),"SM > BNN > TOR",IF(AND(C5=D5,D5=E5),"TOR = SM = BNN","Comb. diferentes"))))) -> SM > BNN > TOR | BD5: =IF(OR(AE5="",AQ5="-"),"",IF(AE5<=0.25,"Tipo 1 (≤0,25) uT",IF(AE5<=0.5,"Tipo 2 (0,25-0,50) uT",IF(AE5<=0.75,"Tipo 3 (0,50-0,75) uT","Tipo 4 (>0,75) uT")))) -> Tipo 3 (0,50-0,75) uT | BE5: =IF(OR(AP5="",AZ5="-"),"",IF(AP5<=0.25,"Tipo 1 (≤0,25) uT",IF(AP5<=0.5,"Tipo 2 (0,25-0,50) uT",IF(AP5<=0.75,"Tipo 3 (0,50-0,75) uT","Tipo 4 (>0,75) uT")))) -> Tipo 2 (0,25-0,50) uT | BF5: =IF(OR(AF5="",AQ5="-"),"",IF(AF5<=0.25,"Tipo 1 (≤0,25) uT",IF(AF5<=0.5,"Tipo 2 (0,25-0,50) uT",IF(AF5<=0.75,"Tipo 3 (0,50-0,75) uT","Tipo 4 (>0,75) uT")))) -> Tipo 1 (≤0,25) uT | BG5: =IF(OR(AQ5="",AQ5="-"),"",IF(AQ5<=0.25,"Tipo 1 (≤0,25) uT",IF(AQ5<=0.5,"Tipo 2 (0,25-0,50) uT",IF(AQ5<=0.75,"Tipo 3 (0,50-0,75) uT","Tipo 4 (>0,75) uT")))) -> Tipo 1 (≤0,25) uT | BH5: =IF(OR(R5="",R5="-"),"",IF(R5<=0.25,"Tipo 1 (≤0,25) uT",IF(R5<=0.5,"Tipo 2 (0,25-0,50) uT",IF(R5<=0.75,"Tipo 3 (0,50-0,75) uT","Tipo 4 (>0,75) uT")))) -> Tipo 2 (0,25-0,50) uT
A6: 46259 | B6: 0.89583333 | C6: 338 | D6: 1581 | E6: 349 | F6: 2240 | G6: N | H6: 9.8 | I6: -141 | J6: 90 | K6: 90 | L6: 90 | M6: 25.5 | N6: 6.6 | O6: 1.12 | P6: 6 | Q6: 7.2 | R6: 0.31 | S6: 22.36 | T6: 0.88 | U6: 0.7 | V6: =(O6+0.3*H6+2)*(F6/2/Z6) -> 1696.8 | W6: =S6*(U6*AA6*0.987-T6)*AB6 -> 1294.2895 | X6: =W6/V6 -> 0.76278257 | Y6: 3 | Z6: 4 | AA6: 6.51 | AB6: 16 | AC6: 6.2 | AD6: 4.7 | AE6: 0.3 | AF6: 0.2 | AG6: =(O6+0.3*H6+2)*(F6/2/AK6) -> 1696.8 | AH6: =S6*(U6*AL6*0.987-T6)*AM6 -> 1778.8184 | AI6: =AH6/AG6 -> 1.0483371 | AJ6: 3 | AK6: 4 | AL6: 6.28 | AM6: 23 | AN6: 6.2 | AO6: 5 | AP6: 0.35 | AQ6: 0.21 | AR6: =SUM(C6:E6) -> 2268 | AS6: =C6/AR6 -> 0.14902998 | AT6: =D6/AR6 -> 0.69708995 | AU6: =E6/AR6 -> 0.15388007 | AV6: =IF(AND(F6<>"",Z6<>""),AB6/(F6/2/Z6),"") -> 0.057142857 | AW6: =IF(AND(F6<>"",AK6<>""),AM6/(F6/2/AK6),"") -> 0.082142857 | AX6: =IF(AND(AQ6<>"",1-(AQ6/O6)>0),1-(AQ6/O6),"") -> 0.8125 | AY6: =IF(AND(AF6<>"",1-(AF6/O6)>0),1-(AF6/O6),"") -> 0.82142857 | AZ6: =IF(Q6="","",IF(Q6<2.5,"Alc. Bruta < 2,5 mg/L",IF(Q6<5,"2,5 ≤ Alc. Bruta < 5,0 mg/L",IF(Q6<7.5,"5,0 ≤ Alc. Bruta < 7,5 mg/L",IF(Q6<10,"7,5 ≤ Alc. Bruta < 10,0 mg/L",IF(Q6<15,"10,0 ≤ Alca. Bruta < 15,0 mg/L","Alc. Bruta > 15 mg/L")))))) -> 5,0 ≤ Alc. Bruta < 7,5 mg/L | BA6: =IF(P6="","",IF(P6<5,"Cor <5 uC",IF(P6<10,"5 ≤ Cor < 10 uC",IF(P6<15,"10 ≤ Cor <15 uC",IF(P6<30,"15 ≤ Cor < 30 uC",IF(P6<50,"30 ≤ Cor < 50 uC","Cor > 50 uC")))))) -> 5 ≤ Cor < 10 uC | BB6: =IF(O6="","",IF(O6<2.5,"Turbidez < 2,5 uT",IF(O6<5,"2,5 ≤ Turb < 5,0 uT",IF(O6<7.5,"5,0 ≤ Turb < 7,5 uT",IF(O6<10,"7,5 ≤ Turb < 10,0 uT",IF(O6<15,"10,0 ≤ Turb < 15,0 uT","Turb > 15 uT")))))) -> Turbidez < 2,5 uT | BC6: =IF(AND(C6>D6,D6>E6),"TOR > SM > BNN",IF(AND(C6>E6,E6>D6),"TOR > BNN > SM",IF(AND(D6>C6,C6>E6),"SM > TOR > BNN",IF(AND(D6>E6,E6>C6),"SM > BNN > TOR",IF(AND(C6=D6,D6=E6),"TOR = SM = BNN","Comb. diferentes"))))) -> SM > BNN > TOR | BD6: =IF(OR(AE6="",AQ6="-"),"",IF(AE6<=0.25,"Tipo 1 (≤0,25) uT",IF(AE6<=0.5,"Tipo 2 (0,25-0,50) uT",IF(AE6<=0.75,"Tipo 3 (0,50-0,75) uT","Tipo 4 (>0,75) uT")))) -> Tipo 2 (0,25-0,50) uT | BE6: =IF(OR(AP6="",AZ6="-"),"",IF(AP6<=0.25,"Tipo 1 (≤0,25) uT",IF(AP6<=0.5,"Tipo 2 (0,25-0,50) uT",IF(AP6<=0.75,"Tipo 3 (0,50-0,75) uT","Tipo 4 (>0,75) uT")))) -> Tipo 2 (0,25-0,50) uT | BF6: =IF(OR(AF6="",AQ6="-"),"",IF(AF6<=0.25,"Tipo 1 (≤0,25) uT",IF(AF6<=0.5,"Tipo 2 (0,25-0,50) uT",IF(AF6<=0.75,"Tipo 3 (0,50-0,75) uT","Tipo 4 (>0,75) uT")))) -> Tipo 1 (≤0,25) uT | BG6: =IF(OR(AQ6="",AQ6="-"),"",IF(AQ6<=0.25,"Tipo 1 (≤0,25) uT",IF(AQ6<=0.5,"Tipo 2 (0,25-0,50) uT",IF(AQ6<=0.75,"Tipo 3 (0,50-0,75) uT","Tipo 4 (>0,75) uT")))) -> Tipo 1 (≤0,25) uT | BH6: =IF(OR(R6="",R6="-"),"",IF(R6<=0.25,"Tipo 1 (≤0,25) uT",IF(R6<=0.5,"Tipo 2 (0,25-0,50) uT",IF(R6<=0.75,"Tipo 3 (0,50-0,75) uT","Tipo 4 (>0,75) uT")))) -> Tipo 2 (0,25-0,50) uT
A7: 46259 | B7: 0.97916667 | C7: 329 | D7: 1349 | E7: 350 | F7: 2330 | G7: N | H7: 9.8 | I7: -145 | J7: 90 | K7: 90 | L7: 90 | M7: 24.5 | N7: 6.5 | O7: 1.13 | P7: 7 | Q7: 6 | R7: 0.33 | S7: 22.36 | T7: 0.88 | U7: 0.7 | V7: =(O7+0.3*H7+2)*(F7/2/Z7) -> 1767.8875 | W7: =S7*(U7*AA7*0.987-T7)*AB7 -> 1362.0513 | X7: =W7/V7 -> 0.77044003 | Y7: 3 | Z7: 4 | AA7: 6.46 | AB7: 17 | AC7: 6.3 | AD7: 6 | AE7: 0.42 | AF7: 0.19 | AG7: =(O7+0.3*H7+2)*(F7/2/AK7) -> 1767.8875 | AH7: =S7*(U7*AL7*0.987-T7)*AM7 -> 1771.7121 | AI7: =AH7/AG7 -> 1.0021634 | AJ7: 3 | AK7: 4 | AL7: 6.26 | AM7: 23 | AN7: 6.1 | AO7: 4.9 | AP7: 0.42 | AQ7: 0.21 | AR7: =SUM(C7:E7) -> 2028 | AS7: =C7/AR7 -> 0.1622288 | AT7: =D7/AR7 -> 0.66518738 | AU7: =E7/AR7 -> 0.17258383 | AV7: =IF(AND(F7<>"",Z7<>""),AB7/(F7/2/Z7),"") -> 0.058369099 | AW7: =IF(AND(F7<>"",AK7<>""),AM7/(F7/2/AK7),"") -> 0.078969957 | AX7: =IF(AND(AQ7<>"",1-(AQ7/O7)>0),1-(AQ7/O7),"") -> 0.81415929 | AY7: =IF(AND(AF7<>"",1-(AF7/O7)>0),1-(AF7/O7),"") -> 0.83185841 | AZ7: =IF(Q7="","",IF(Q7<2.5,"Alc. Bruta < 2,5 mg/L",IF(Q7<5,"2,5 ≤ Alc. Bruta < 5,0 mg/L",IF(Q7<7.5,"5,0 ≤ Alc. Bruta < 7,5 mg/L",IF(Q7<10,"7,5 ≤ Alc. Bruta < 10,0 mg/L",IF(Q7<15,"10,0 ≤ Alca. Bruta < 15,0 mg/L","Alc. Bruta > 15 mg/L")))))) -> 5,0 ≤ Alc. Bruta < 7,5 mg/L | BA7: =IF(P7="","",IF(P7<5,"Cor <5 uC",IF(P7<10,"5 ≤ Cor < 10 uC",IF(P7<15,"10 ≤ Cor <15 uC",IF(P7<30,"15 ≤ Cor < 30 uC",IF(P7<50,"30 ≤ Cor < 50 uC","Cor > 50 uC")))))) -> 5 ≤ Cor < 10 uC | BB7: =IF(O7="","",IF(O7<2.5,"Turbidez < 2,5 uT",IF(O7<5,"2,5 ≤ Turb < 5,0 uT",IF(O7<7.5,"5,0 ≤ Turb < 7,5 uT",IF(O7<10,"7,5 ≤ Turb < 10,0 uT",IF(O7<15,"10,0 ≤ Turb < 15,0 uT","Turb > 15 uT")))))) -> Turbidez < 2,5 uT | BC7: =IF(AND(C7>D7,D7>E7),"TOR > SM > BNN",IF(AND(C7>E7,E7>D7),"TOR > BNN > SM",IF(AND(D7>C7,C7>E7),"SM > TOR > BNN",IF(AND(D7>E7,E7>C7),"SM > BNN > TOR",IF(AND(C7=D7,D7=E7),"TOR = SM = BNN","Comb. diferentes"))))) -> SM > BNN > TOR | BD7: =IF(OR(AE7="",AQ7="-"),"",IF(AE7<=0.25,"Tipo 1 (≤0,25) uT",IF(AE7<=0.5,"Tipo 2 (0,25-0,50) uT",IF(AE7<=0.75,"Tipo 3 (0,50-0,75) uT","Tipo 4 (>0,75) uT")))) -> Tipo 2 (0,25-0,50) uT | BE7: =IF(OR(AP7="",AZ7="-"),"",IF(AP7<=0.25,"Tipo 1 (≤0,25) uT",IF(AP7<=0.5,"Tipo 2 (0,25-0,50) uT",IF(AP7<=0.75,"Tipo 3 (0,50-0,75) uT","Tipo 4 (>0,75) uT")))) -> Tipo 2 (0,25-0,50) uT | BF7: =IF(OR(AF7="",AQ7="-"),"",IF(AF7<=0.25,"Tipo 1 (≤0,25) uT",IF(AF7<=0.5,"Tipo 2 (0,25-0,50) uT",IF(AF7<=0.75,"Tipo 3 (0,50-0,75) uT","Tipo 4 (>0,75) uT")))) -> Tipo 1 (≤0,25) uT | BG7: =IF(OR(AQ7="",AQ7="-"),"",IF(AQ7<=0.25,"Tipo 1 (≤0,25) uT",IF(AQ7<=0.5,"Tipo 2 (0,25-0,50) uT",IF(AQ7<=0.75,"Tipo 3 (0,50-0,75) uT","Tipo 4 (>0,75) uT")))) -> Tipo 1 (≤0,25) uT | BH7: =IF(OR(R7="",R7="-"),"",IF(R7<=0.25,"Tipo 1 (≤0,25) uT",IF(R7<=0.5,"Tipo 2 (0,25-0,50) uT",IF(R7<=0.75,"Tipo 3 (0,50-0,75) uT","Tipo 4 (>0,75) uT")))) -> Tipo 2 (0,25-0,50) uT
A8: 46260 | B8: 0.14583333 | C8: 333 | D8: 1525 | E8: 340 | F8: 2249 | G8: N | H8: 9.8 | I8: -151 | J8: 90 | K8: 90 | L8: 90 | M8: 24.3 | N8: 6.6 | O8: 0.98 | P8: 6 | Q8: 7.4 | R8: 0.3 | S8: 22.36 | T8: 0.88 | U8: 0.7 | V8: =(O8+0.3*H8+2)*(F8/2/Z8) -> 1664.26 | W8: =S8*(U8*AA8*0.987-T8)*AB8 -> 1372.5563 | X8: =W8/V8 -> 0.82472468 | Y8: 3 | Z8: 4 | AA8: 6.5 | AB8: 17 | AC8: 6.3 | AD8: 4.9 | AE8: 0.3 | AF8: 0.18 | AG8: =(O8+0.3*H8+2)*(F8/2/AK8) -> 1664.26 | AH8: =S8*(U8*AL8*0.987-T8)*AM8 -> 1775.2652 | AI8: =AH8/AG8 -> 1.0666995 | AJ8: 3 | AK8: 4 | AL8: 6.27 | AM8: 23 | AN8: 6.2 | AO8: 3.8 | AP8: 0.3 | AQ8: 0.21 | AR8: =SUM(C8:E8) -> 2198 | AS8: =C8/AR8 -> 0.15150136 | AT8: =D8/AR8 -> 0.69381256 | AU8: =E8/AR8 -> 0.15468608 | AV8: =IF(AND(F8<>"",Z8<>""),AB8/(F8/2/Z8),"") -> 0.060471321 | AW8: =IF(AND(F8<>"",AK8<>""),AM8/(F8/2/AK8),"") -> 0.08181414 | AX8: =IF(AND(AQ8<>"",1-(AQ8/O8)>0),1-(AQ8/O8),"") -> 0.78571429 | AY8: =IF(AND(AF8<>"",1-(AF8/O8)>0),1-(AF8/O8),"") -> 0.81632653 | AZ8: =IF(Q8="","",IF(Q8<2.5,"Alc. Bruta < 2,5 mg/L",IF(Q8<5,"2,5 ≤ Alc. Bruta < 5,0 mg/L",IF(Q8<7.5,"5,0 ≤ Alc. Bruta < 7,5 mg/L",IF(Q8<10,"7,5 ≤ Alc. Bruta < 10,0 mg/L",IF(Q8<15,"10,0 ≤ Alca. Bruta < 15,0 mg/L","Alc. Bruta > 15 mg/L")))))) -> 5,0 ≤ Alc. Bruta < 7,5 mg/L | BA8: =IF(P8="","",IF(P8<5,"Cor <5 uC",IF(P8<10,"5 ≤ Cor < 10 uC",IF(P8<15,"10 ≤ Cor <15 uC",IF(P8<30,"15 ≤ Cor < 30 uC",IF(P8<50,"30 ≤ Cor < 50 uC","Cor > 50 uC")))))) -> 5 ≤ Cor < 10 uC | BB8: =IF(O8="","",IF(O8<2.5,"Turbidez < 2,5 uT",IF(O8<5,"2,5 ≤ Turb < 5,0 uT",IF(O8<7.5,"5,0 ≤ Turb < 7,5 uT",IF(O8<10,"7,5 ≤ Turb < 10,0 uT",IF(O8<15,"10,0 ≤ Turb < 15,0 uT","Turb > 15 uT")))))) -> Turbidez < 2,5 uT | BC8: =IF(AND(C8>D8,D8>E8),"TOR > SM > BNN",IF(AND(C8>E8,E8>D8),"TOR > BNN > SM",IF(AND(D8>C8,C8>E8),"SM > TOR > BNN",IF(AND(D8>E8,E8>C8),"SM > BNN > TOR",IF(AND(C8=D8,D8=E8),"TOR = SM = BNN","Comb. diferentes"))))) -> SM > BNN > TOR | BD8: =IF(OR(AE8="",AQ8="-"),"",IF(AE8<=0.25,"Tipo 1 (≤0,25) uT",IF(AE8<=0.5,"Tipo 2 (0,25-0,50) uT",IF(AE8<=0.75,"Tipo 3 (0,50-0,75) uT","Tipo 4 (>0,75) uT")))) -> Tipo 2 (0,25-0,50) uT | BE8: =IF(OR(AP8="",AZ8="-"),"",IF(AP8<=0.25,"Tipo 1 (≤0,25) uT",IF(AP8<=0.5,"Tipo 2 (0,25-0,50) uT",IF(AP8<=0.75,"Tipo 3 (0,50-0,75) uT","Tipo 4 (>0,75) uT")))) -> Tipo 2 (0,25-0,50) uT | BF8: =IF(OR(AF8="",AQ8="-"),"",IF(AF8<=0.25,"Tipo 1 (≤0,25) uT",IF(AF8<=0.5,"Tipo 2 (0,25-0,50) uT",IF(AF8<=0.75,"Tipo 3 (0,50-0,75) uT","Tipo 4 (>0,75) uT")))) -> Tipo 1 (≤0,25) uT | BG8: =IF(OR(AQ8="",AQ8="-"),"",IF(AQ8<=0.25,"Tipo 1 (≤0,25) uT",IF(AQ8<=0.5,"Tipo 2 (0,25-0,50) uT",IF(AQ8<=0.75,"Tipo 3 (0,50-0,75) uT","Tipo 4 (>0,75) uT")))) -> Tipo 1 (≤0,25) uT | BH8: =IF(OR(R8="",R8="-"),"",IF(R8<=0.25,"Tipo 1 (≤0,25) uT",IF(R8<=0.5,"Tipo 2 (0,25-0,50) uT",IF(R8<=0.75,"Tipo 3 (0,50-0,75) uT","Tipo 4 (>0,75) uT")))) -> Tipo 2 (0,25-0,50) uT
A9: 46260 | B9: 0.22916667 | C9: 335 | D9: 1545 | E9: 349 | F9: 2320 | G9: N | H9: 9.8 | I9: -145 | J9: 90 | K9: 90 | L9: 90 | M9: 24.2 | N9: 6.6 | O9: 0.87 | P9: 5 | Q9: 7 | R9: 0.34 | S9: 22.36 | T9: 0.88 | U9: 0.7 | V9: =(O9+0.3*H9+2)*(F9/2/Z9) -> 1684.9 | W9: =S9*(U9*AA9*0.987-T9)*AB9 -> 1375.1826 | X9: =W9/V9 -> 0.81618052 | Y9: 3 | Z9: 4 | AA9: 6.51 | AB9: 17 | AC9: 6.3 | AD9: 5.1 | AE9: 0.3 | AF9: 0.2 | AG9: =(O9+0.3*H9+2)*(F9/2/AK9) -> 1684.9 | AH9: =S9*(U9*AL9*0.987-T9)*AM9 -> 1775.2652 | AI9: =AH9/AG9 -> 1.0536324 | AJ9: 3 | AK9: 4 | AL9: 6.27 | AM9: 23 | AN9: 6.2 | AO9: 4.3 | AP9: 0.27 | AQ9: 0.25 | AR9: =SUM(C9:E9) -> 2229 | AS9: =C9/AR9 -> 0.15029161 | AT9: =D9/AR9 -> 0.69313594 | AU9: =E9/AR9 -> 0.15657245 | AV9: =IF(AND(F9<>"",Z9<>""),AB9/(F9/2/Z9),"") -> 0.05862069 | AW9: =IF(AND(F9<>"",AK9<>""),AM9/(F9/2/AK9),"") -> 0.079310345 | AX9: =IF(AND(AQ9<>"",1-(AQ9/O9)>0),1-(AQ9/O9),"") -> 0.71264368 | AY9: =IF(AND(AF9<>"",1-(AF9/O9)>0),1-(AF9/O9),"") -> 0.77011494 | AZ9: =IF(Q9="","",IF(Q9<2.5,"Alc. Bruta < 2,5 mg/L",IF(Q9<5,"2,5 ≤ Alc. Bruta < 5,0 mg/L",IF(Q9<7.5,"5,0 ≤ Alc. Bruta < 7,5 mg/L",IF(Q9<10,"7,5 ≤ Alc. Bruta < 10,0 mg/L",IF(Q9<15,"10,0 ≤ Alca. Bruta < 15,0 mg/L","Alc. Bruta > 15 mg/L")))))) -> 5,0 ≤ Alc. Bruta < 7,5 mg/L | BA9: =IF(P9="","",IF(P9<5,"Cor <5 uC",IF(P9<10,"5 ≤ Cor < 10 uC",IF(P9<15,"10 ≤ Cor <15 uC",IF(P9<30,"15 ≤ Cor < 30 uC",IF(P9<50,"30 ≤ Cor < 50 uC","Cor > 50 uC")))))) -> 5 ≤ Cor < 10 uC | BB9: =IF(O9="","",IF(O9<2.5,"Turbidez < 2,5 uT",IF(O9<5,"2,5 ≤ Turb < 5,0 uT",IF(O9<7.5,"5,0 ≤ Turb < 7,5 uT",IF(O9<10,"7,5 ≤ Turb < 10,0 uT",IF(O9<15,"10,0 ≤ Turb < 15,0 uT","Turb > 15 uT")))))) -> Turbidez < 2,5 uT | BC9: =IF(AND(C9>D9,D9>E9),"TOR > SM > BNN",IF(AND(C9>E9,E9>D9),"TOR > BNN > SM",IF(AND(D9>C9,C9>E9),"SM > TOR > BNN",IF(AND(D9>E9,E9>C9),"SM > BNN > TOR",IF(AND(C9=D9,D9=E9),"TOR = SM = BNN","Comb. diferentes"))))) -> SM > BNN > TOR | BD9: =IF(OR(AE9="",AQ9="-"),"",IF(AE9<=0.25,"Tipo 1 (≤0,25) uT",IF(AE9<=0.5,"Tipo 2 (0,25-0,50) uT",IF(AE9<=0.75,"Tipo 3 (0,50-0,75) uT","Tipo 4 (>0,75) uT")))) -> Tipo 2 (0,25-0,50) uT | BE9: =IF(OR(AP9="",AZ9="-"),"",IF(AP9<=0.25,"Tipo 1 (≤0,25) uT",IF(AP9<=0.5,"Tipo 2 (0,25-0,50) uT",IF(AP9<=0.75,"Tipo 3 (0,50-0,75) uT","Tipo 4 (>0,75) uT")))) -> Tipo 2 (0,25-0,50) uT | BF9: =IF(OR(AF9="",AQ9="-"),"",IF(AF9<=0.25,"Tipo 1 (≤0,25) uT",IF(AF9<=0.5,"Tipo 2 (0,25-0,50) uT",IF(AF9<=0.75,"Tipo 3 (0,50-0,75) uT","Tipo 4 (>0,75) uT")))) -> Tipo 1 (≤0,25) uT | BG9: =IF(OR(AQ9="",AQ9="-"),"",IF(AQ9<=0.25,"Tipo 1 (≤0,25) uT",IF(AQ9<=0.5,"Tipo 2 (0,25-0,50) uT",IF(AQ9<=0.75,"Tipo 3 (0,50-0,75) uT","Tipo 4 (>0,75) uT")))) -> Tipo 1 (≤0,25) uT | BH9: =IF(OR(R9="",R9="-"),"",IF(R9<=0.25,"Tipo 1 (≤0,25) uT",IF(R9<=0.5,"Tipo 2 (0,25-0,50) uT",IF(R9<=0.75,"Tipo 3 (0,50-0,75) uT","Tipo 4 (>0,75) uT")))) -> Tipo 2 (0,25-0,50) uT
A10: 46260 | B10: 0.3125 | C10: 317 | D10: 1510 | E10: 350 | F10: 2320 | G10: N | H10: 9.8 | I10: -150.8 | J10: 90 | K10: 90 | L10: 90 | M10: 24.9 | N10: 6.4 | O10: 0.97 | P10: 7 | Q10: 6.9 | R10: 0.39 | S10: 22.36 | T10: 0.88 | U10: 0.7 | V10: =(O10+0.3*H10+2)*(F10/2/Z10) -> 2285.2 | W10: =S10*(U10*AA10*0.987-T10)*AB10 -> 1372.5563 | X10: =W10/V10 -> 0.60062852 | Y10: 3 | Z10: 3 | AA10: 6.5 | AB10: 17 | AC10: 6.2 | AD10: 4.9 | AE10: 0.29 | AF10: 0.23 | AG10: =(O10+0.3*H10+2)*(F10/2/AK10) -> 2285.2 | AH10: =S10*(U10*AL10*0.987-T10)*AM10 -> 1768.1589 | AI10: =AH10/AG10 -> 0.77374362 | AJ10: 3 | AK10: 3 | AL10: 6.25 | AM10: 23 | AN10: 6.2 | AO10: 6 | AP10: 0.38 | AQ10: 0.26 | AR10: =SUM(C10:E10) -> 2177 | AS10: =C10/AR10 -> 0.14561323 | AT10: =D10/AR10 -> 0.69361507 | AU10: =E10/AR10 -> 0.1607717 | AV10: =IF(AND(F10<>"",Z10<>""),AB10/(F10/2/Z10),"") -> 0.043965517 | AW10: =IF(AND(F10<>"",AK10<>""),AM10/(F10/2/AK10),"") -> 0.059482759 | AX10: =IF(AND(AQ10<>"",1-(AQ10/O10)>0),1-(AQ10/O10),"") -> 0.73195876 | AY10: =IF(AND(AF10<>"",1-(AF10/O10)>0),1-(AF10/O10),"") -> 0.7628866 | AZ10: =IF(Q10="","",IF(Q10<2.5,"Alc. Bruta < 2,5 mg/L",IF(Q10<5,"2,5 ≤ Alc. Bruta < 5,0 mg/L",IF(Q10<7.5,"5,0 ≤ Alc. Bruta < 7,5 mg/L",IF(Q10<10,"7,5 ≤ Alc. Bruta < 10,0 mg/L",IF(Q10<15,"10,0 ≤ Alca. Bruta < 15,0 mg/L","Alc. Bruta > 15 mg/L")))))) -> 5,0 ≤ Alc. Bruta < 7,5 mg/L | BA10: =IF(P10="","",IF(P10<5,"Cor <5 uC",IF(P10<10,"5 ≤ Cor < 10 uC",IF(P10<15,"10 ≤ Cor <15 uC",IF(P10<30,"15 ≤ Cor < 30 uC",IF(P10<50,"30 ≤ Cor < 50 uC","Cor > 50 uC")))))) -> 5 ≤ Cor < 10 uC | BB10: =IF(O10="","",IF(O10<2.5,"Turbidez < 2,5 uT",IF(O10<5,"2,5 ≤ Turb < 5,0 uT",IF(O10<7.5,"5,0 ≤ Turb < 7,5 uT",IF(O10<10,"7,5 ≤ Turb < 10,0 uT",IF(O10<15,"10,0 ≤ Turb < 15,0 uT","Turb > 15 uT")))))) -> Turbidez < 2,5 uT | BC10: =IF(AND(C10>D10,D10>E10),"TOR > SM > BNN",IF(AND(C10>E10,E10>D10),"TOR > BNN > SM",IF(AND(D10>C10,C10>E10),"SM > TOR > BNN",IF(AND(D10>E10,E10>C10),"SM > BNN > TOR",IF(AND(C10=D10,D10=E10),"TOR = SM = BNN","Comb. diferentes"))))) -> SM > BNN > TOR | BD10: =IF(OR(AE10="",AQ10="-"),"",IF(AE10<=0.25,"Tipo 1 (≤0,25) uT",IF(AE10<=0.5,"Tipo 2 (0,25-0,50) uT",IF(AE10<=0.75,"Tipo 3 (0,50-0,75) uT","Tipo 4 (>0,75) uT")))) -> Tipo 2 (0,25-0,50) uT | BE10: =IF(OR(AP10="",AZ10="-"),"",IF(AP10<=0.25,"Tipo 1 (≤0,25) uT",IF(AP10<=0.5,"Tipo 2 (0,25-0,50) uT",IF(AP10<=0.75,"Tipo 3 (0,50-0,75) uT","Tipo 4 (>0,75) uT")))) -> Tipo 2 (0,25-0,50) uT | BF10: =IF(OR(AF10="",AQ10="-"),"",IF(AF10<=0.25,"Tipo 1 (≤0,25) uT",IF(AF10<=0.5,"Tipo 2 (0,25-0,50) uT",IF(AF10<=0.75,"Tipo 3 (0,50-0,75) uT","Tipo 4 (>0,75) uT")))) -> Tipo 1 (≤0,25) uT | BG10: =IF(OR(AQ10="",AQ10="-"),"",IF(AQ10<=0.25,"Tipo 1 (≤0,25) uT",IF(AQ10<=0.5,"Tipo 2 (0,25-0,50) uT",IF(AQ10<=0.75,"Tipo 3 (0,50-0,75) uT","Tipo 4 (>0,75) uT")))) -> Tipo 2 (0,25-0,50) uT | BH10: =IF(OR(R10="",R10="-"),"",IF(R10<=0.25,"Tipo 1 (≤0,25) uT",IF(R10<=0.5,"Tipo 2 (0,25-0,50) uT",IF(R10<=0.75,"Tipo 3 (0,50-0,75) uT","Tipo 4 (>0,75) uT")))) -> Tipo 2 (0,25-0,50) uT
A11: 46260 | B11: 0.47916667 | C11: 295 | D11: 1560 | E11: 349 | F11: 2150 | G11: N | H11: 10.8 | I11: -154 | J11: 90 | K11: 90 | L11: 90 | M11: 26.1 | N11: 6.5 | O11: 0.96 | P11: 5 | Q11: 8 | R11: 0.24 | S11: 22.36 | T11: 0.88 | U11: 0.7 | V11: =(O11+0.3*H11+2)*(F11/2/Z11) -> 2221.6667 | W11: =S11*(U11*AA11*0.987-T11)*AB11 -> 1372.5563 | X11: =W11/V11 -> 0.61780479 | Y11: 3 | Z11: 3 | AA11: 6.5 | AB11: 17 | AC11: 6.2 | AD11: 5.2 | AE11: 0.26 | AF11: 0.17 | AG11: =(O11+0.3*H11+2)*(F11/2/AK11) -> 2221.6667 | AH11: =S11*(U11*AL11*0.987-T11)*AM11 -> 1750.3931 | AI11: =AH11/AG11 -> 0.78787387 | AJ11: 3 | AK11: 3 | AL11: 6.2 | AM11: 23 | AN11: 6.1 | AO11: 5.4 | AP11: 0.27 | AQ11: 0.19 | AR11: =SUM(C11:E11) -> 2204 | AS11: =C11/AR11 -> 0.13384755 | AT11: =D11/AR11 -> 0.70780399 | AU11: =E11/AR11 -> 0.15834846 | AV11: =IF(AND(F11<>"",Z11<>""),AB11/(F11/2/Z11),"") -> 0.04744186 | AW11: =IF(AND(F11<>"",AK11<>""),AM11/(F11/2/AK11),"") -> 0.064186047 | AX11: =IF(AND(AQ11<>"",1-(AQ11/O11)>0),1-(AQ11/O11),"") -> 0.80208333 | AY11: =IF(AND(AF11<>"",1-(AF11/O11)>0),1-(AF11/O11),"") -> 0.82291667 | AZ11: =IF(Q11="","",IF(Q11<2.5,"Alc. Bruta < 2,5 mg/L",IF(Q11<5,"2,5 ≤ Alc. Bruta < 5,0 mg/L",IF(Q11<7.5,"5,0 ≤ Alc. Bruta < 7,5 mg/L",IF(Q11<10,"7,5 ≤ Alc. Bruta < 10,0 mg/L",IF(Q11<15,"10,0 ≤ Alca. Bruta < 15,0 mg/L","Alc. Bruta > 15 mg/L")))))) -> 7,5 ≤ Alc. Bruta < 10,0 mg/L | BA11: =IF(P11="","",IF(P11<5,"Cor <5 uC",IF(P11<10,"5 ≤ Cor < 10 uC",IF(P11<15,"10 ≤ Cor <15 uC",IF(P11<30,"15 ≤ Cor < 30 uC",IF(P11<50,"30 ≤ Cor < 50 uC","Cor > 50 uC")))))) -> 5 ≤ Cor < 10 uC | BB11: =IF(O11="","",IF(O11<2.5,"Turbidez < 2,5 uT",IF(O11<5,"2,5 ≤ Turb < 5,0 uT",IF(O11<7.5,"5,0 ≤ Turb < 7,5 uT",IF(O11<10,"7,5 ≤ Turb < 10,0 uT",IF(O11<15,"10,0 ≤ Turb < 15,0 uT","Turb > 15 uT")))))) -> Turbidez < 2,5 uT | BC11: =IF(AND(C11>D11,D11>E11),"TOR > SM > BNN",IF(AND(C11>E11,E11>D11),"TOR > BNN > SM",IF(AND(D11>C11,C11>E11),"SM > TOR > BNN",IF(AND(D11>E11,E11>C11),"SM > BNN > TOR",IF(AND(C11=D11,D11=E11),"TOR = SM = BNN","Comb. diferentes"))))) -> SM > BNN > TOR | BD11: =IF(OR(AE11="",AQ11="-"),"",IF(AE11<=0.25,"Tipo 1 (≤0,25) uT",IF(AE11<=0.5,"Tipo 2 (0,25-0,50) uT",IF(AE11<=0.75,"Tipo 3 (0,50-0,75) uT","Tipo 4 (>0,75) uT")))) -> Tipo 2 (0,25-0,50) uT | BE11: =IF(OR(AP11="",AZ11="-"),"",IF(AP11<=0.25,"Tipo 1 (≤0,25) uT",IF(AP11<=0.5,"Tipo 2 (0,25-0,50) uT",IF(AP11<=0.75,"Tipo 3 (0,50-0,75) uT","Tipo 4 (>0,75) uT")))) -> Tipo 2 (0,25-0,50) uT | BF11: =IF(OR(AF11="",AQ11="-"),"",IF(AF11<=0.25,"Tipo 1 (≤0,25) uT",IF(AF11<=0.5,"Tipo 2 (0,25-0,50) uT",IF(AF11<=0.75,"Tipo 3 (0,50-0,75) uT","Tipo 4 (>0,75) uT")))) -> Tipo 1 (≤0,25) uT | BG11: =IF(OR(AQ11="",AQ11="-"),"",IF(AQ11<=0.25,"Tipo 1 (≤0,25) uT",IF(AQ11<=0.5,"Tipo 2 (0,25-0,50) uT",IF(AQ11<=0.75,"Tipo 3 (0,50-0,75) uT","Tipo 4 (>0,75) uT")))) -> Tipo 1 (≤0,25) uT | BH11: =IF(OR(R11="",R11="-"),"",IF(R11<=0.25,"Tipo 1 (≤0,25) uT",IF(R11<=0.5,"Tipo 2 (0,25-0,50) uT",IF(R11<=0.75,"Tipo 3 (0,50-0,75) uT","Tipo 4 (>0,75) uT")))) -> Tipo 1 (≤0,25) uT
A12: 46260 | B12: 0.64583333 | C12: 320 | D12: 1505 | E12: 350 | F12: 2155 | G12: N | H12: 10.8 | I12: -154 | J12: 90 | K12: 90 | L12: 90 | M12: 27.2 | N12: 6.4 | O12: 0.9 | P12: 6 | Q12: 7.6 | R12: 0.23 | S12: 22.36 | T12: 0.88 | U12: 0.7 | V12: =(O12+0.3*H12+2)*(F12/2/Z12) -> 2205.2833 | W12: =S12*(U12*AA12*0.987-T12)*AB12 -> 1372.5563 | X12: =W12/V12 -> 0.62239454 | Y12: 3 | Z12: 3 | AA12: 6.5 | AB12: 17 | AC12: 6.4 | AD12: 6 | AE12: 0.23 | AF12: 0.153 | AG12: =(O12+0.3*H12+2)*(F12/2/AK12) -> 2205.2833 | AH12: =S12*(U12*AL12*0.987-T12)*AM12 -> 1714.8615 | AI12: =AH12/AG12 -> 0.77761505 | AJ12: 3 | AK12: 3 | AL12: 6.1 | AM12: 23 | AN12: 5.2 | AO12: 2.6 | AP12: 0.15 | AQ12: 0.18 | AR12: =SUM(C12:E12) -> 2175 | AS12: =C12/AR12 -> 0.14712644 | AT12: =D12/AR12 -> 0.69195402 | AU12: =E12/AR12 -> 0.16091954 | AV12: =IF(AND(F12<>"",Z12<>""),AB12/(F12/2/Z12),"") -> 0.047331787 | AW12: =IF(AND(F12<>"",AK12<>""),AM12/(F12/2/AK12),"") -> 0.064037123 | AX12: =IF(AND(AQ12<>"",1-(AQ12/O12)>0),1-(AQ12/O12),"") -> 0.8 | AY12: =IF(AND(AF12<>"",1-(AF12/O12)>0),1-(AF12/O12),"") -> 0.83 | AZ12: =IF(Q12="","",IF(Q12<2.5,"Alc. Bruta < 2,5 mg/L",IF(Q12<5,"2,5 ≤ Alc. Bruta < 5,0 mg/L",IF(Q12<7.5,"5,0 ≤ Alc. Bruta < 7,5 mg/L",IF(Q12<10,"7,5 ≤ Alc. Bruta < 10,0 mg/L",IF(Q12<15,"10,0 ≤ Alca. Bruta < 15,0 mg/L","Alc. Bruta > 15 mg/L")))))) -> 7,5 ≤ Alc. Bruta < 10,0 mg/L | BA12: =IF(P12="","",IF(P12<5,"Cor <5 uC",IF(P12<10,"5 ≤ Cor < 10 uC",IF(P12<15,"10 ≤ Cor <15 uC",IF(P12<30,"15 ≤ Cor < 30 uC",IF(P12<50,"30 ≤ Cor < 50 uC","Cor > 50 uC")))))) -> 5 ≤ Cor < 10 uC | BB12: =IF(O12="","",IF(O12<2.5,"Turbidez < 2,5 uT",IF(O12<5,"2,5 ≤ Turb < 5,0 uT",IF(O12<7.5,"5,0 ≤ Turb < 7,5 uT",IF(O12<10,"7,5 ≤ Turb < 10,0 uT",IF(O12<15,"10,0 ≤ Turb < 15,0 uT","Turb > 15 uT")))))) -> Turbidez < 2,5 uT | BC12: =IF(AND(C12>D12,D12>E12),"TOR > SM > BNN",IF(AND(C12>E12,E12>D12),"TOR > BNN > SM",IF(AND(D12>C12,C12>E12),"SM > TOR > BNN",IF(AND(D12>E12,E12>C12),"SM > BNN > TOR",IF(AND(C12=D12,D12=E12),"TOR = SM = BNN","Comb. diferentes"))))) -> SM > BNN > TOR | BD12: =IF(OR(AE12="",AQ12="-"),"",IF(AE12<=0.25,"Tipo 1 (≤0,25) uT",IF(AE12<=0.5,"Tipo 2 (0,25-0,50) uT",IF(AE12<=0.75,"Tipo 3 (0,50-0,75) uT","Tipo 4 (>0,75) uT")))) -> Tipo 1 (≤0,25) uT | BE12: =IF(OR(AP12="",AZ12="-"),"",IF(AP12<=0.25,"Tipo 1 (≤0,25) uT",IF(AP12<=0.5,"Tipo 2 (0,25-0,50) uT",IF(AP12<=0.75,"Tipo 3 (0,50-0,75) uT","Tipo 4 (>0,75) uT")))) -> Tipo 1 (≤0,25) uT | BF12: =IF(OR(AF12="",AQ12="-"),"",IF(AF12<=0.25,"Tipo 1 (≤0,25) uT",IF(AF12<=0.5,"Tipo 2 (0,25-0,50) uT",IF(AF12<=0.75,"Tipo 3 (0,50-0,75) uT","Tipo 4 (>0,75) uT")))) -> Tipo 1 (≤0,25) uT | BG12: =IF(OR(AQ12="",AQ12="-"),"",IF(AQ12<=0.25,"Tipo 1 (≤0,25) uT",IF(AQ12<=0.5,"Tipo 2 (0,25-0,50) uT",IF(AQ12<=0.75,"Tipo 3 (0,50-0,75) uT","Tipo 4 (>0,75) uT")))) -> Tipo 1 (≤0,25) uT | BH12: =IF(OR(R12="",R12="-"),"",IF(R12<=0.25,"Tipo 1 (≤0,25) uT",IF(R12<=0.5,"Tipo 2 (0,25-0,50) uT",IF(R12<=0.75,"Tipo 3 (0,50-0,75) uT","Tipo 4 (>0,75) uT")))) -> Tipo 1 (≤0,25) uT
